Workbook

Sheet 인덱스
A1: =TEXT($K$1,"yyyy")&"년 1월~"&MONTH($K$1)&"월 월차 결산서 [ ㈜ 창현 ]" | J1: 결산기준일 | K1: 46234 | L1: (이 날짜만 바꾸면 아래 목록 및 재무상태표(내역)/전월대비증감/매출액대비 비율분석 시트의 기간 문구가 자동으로 바뀝니다)
K2: 46267
A3: I N D E X
A5: NO | B5: 구분
A6: 1 | B6: 핵심지표 요약
A7: 2 | B7: ="재무상태표 ["&TEXT($K$1,"yyyy")&"년"&TEXT(MONTH($K$1),"00")&"월"&TEXT(DAY($K$1),"00")&"일"&" 현재]"
A8: 3 | B8: ="손익계산서(매출액대비 비율분석) ["&TEXT(DATE(YEAR($K$1),1,1),"yyyy")&"년"&TEXT(MONTH(DATE(YEAR($K$1),1,1)),"00")&"월"&TEXT(DAY(DATE(YEAR($K$1),1,1)),"00")&"일"&" 부터 "&TEXT($K$1,"yyyy")&"년"&TEXT(MONTH($K$1),"00")&"월"&TEXT(DAY($K$1),"00")&"일"&" 까지]"
A9: 4 | B9: ="손익계산서(전월대비 증감) ["&TEXT(EOMONTH($K$1,-2)+1,"yyyy")&"년"&TEXT(MONTH(EOMONTH($K$1,-2)+1),"00")&"월"&TEXT(DAY(EOMONTH($K$1,-2)+1),"00")&"일"&" 부터 "&TEXT($K$1,"yyyy")&"년"&TEXT(MONTH($K$1),"00")&"월"&TEXT(DAY($K$1),"00")&"일"&" 까지]"
A10: 5 | B10: ="기간별손익계산서 ["&TEXT(DATE(YEAR($K$1),1,1),"yyyy")&"년"&TEXT(MONTH(DATE(YEAR($K$1),1,1)),"00")&"월"&TEXT(DAY(DATE(YEAR($K$1),1,1)),"00")&"일"&" 부터 "&TEXT($K$1,"yyyy")&"년"&TEXT(MONTH($K$1),"00")&"월"&TEXT(DAY($K$1),"00")&"일"&" 까지]"
A11: 6 | B11: =TEXT($K$1,"yyyy")&"년 차량별 비용현황[연간누계/월별/당월상세]"
A12: 7 | B12: =TEXT($K$1,"yyyy")&"년 운송비 개인별 비용"
D15: 결재 | E15: 담당 | F15: 이사 | G15: 임원 | H15: 사장

Sheet 요약
A1: 핵심지표 요약
A2: =TEXT(인덱스!$K$1,"yyyy")&"년 1월 ~ "&MONTH(인덱스!$K$1)&"월 누적 기준 ( 기준일 : "&TEXT(인덱스!$K$1,"yyyy")&"년"&TEXT(MONTH(인덱스!$K$1),"00")&"월"&TEXT(DAY(인덱스!$K$1),"00")&"일 )"
A4: ■ 손익 요약 (단위: 천원)
A5: 구분 | B5: ="전년동기 대비 ("&(YEAR(인덱스!$K$1)-1)&"년 1~"&MONTH(인덱스!$K$1)&"월)" | F5: 전기 대비 (2025년 연간)
B6: ="당기(1~"&MONTH(인덱스!$K$1)&"월)" | C6: ="전년동기(1~"&MONTH(인덱스!$K$1)&"월)" | D6: 증감액 | E6: 증감률 | F6: 전기(연간) | G6: 증감액 | H6: 증감률
A7: 매출액 | B7: ='매출액대비 비율분석'!C9 | C7: =IFERROR(INDEX('기간별손익계산서(전년동기)'!$B:$B,MATCH(SUBSTITUTE("Ⅰ . 매 출 액"," ","")&"|1",'기간별손익계산서(전년동기)'!$P:$P,0)),0) | D7: =B7-C7 | E7: =IFERROR(IF(C7=0,"",(B7-C7)/ABS(C7)),"") | F7: ='매출액대비 비율분석'!F9 | G7: =B7-F7 | H7: =IFERROR(IF(F7=0,"",(B7-F7)/ABS(F7)),"")
A8: 매출원가 | B8: ='매출액대비 비율분석'!C12 | C8: =IFERROR(INDEX('기간별손익계산서(전년동기)'!$B:$B,MATCH(SUBSTITUTE("Ⅱ . 매 출 원 가"," ","")&"|1",'기간별손익계산서(전년동기)'!$P:$P,0)),0) | D8: =B8-C8 | E8: =IFERROR(IF(C8=0,"",(B8-C8)/ABS(C8)),"") | F8: ='매출액대비 비율분석'!F12 | G8: =B8-F8 | H8: =IFERROR(IF(F8=0,"",(B8-F8)/ABS(F8)),"")
A9: 매출총이익 | B9: ='매출액대비 비율분석'!C18 | C9: =IFERROR(INDEX('기간별손익계산서(전년동기)'!$B:$B,MATCH(SUBSTITUTE("Ⅲ . 매 출 총 이 익"," ","")&"|1",'기간별손익계산서(전년동기)'!$P:$P,0)),0) | D9: =B9-C9 | E9: =IFERROR(IF(C9=0,"",(B9-C9)/ABS(C9)),"") | F9: ='매출액대비 비율분석'!F18 | G9: =B9-F9 | H9: =IFERROR(IF(F9=0,"",(B9-F9)/ABS(F9)),"")
A10: 판매관리비 | B10: ='매출액대비 비율분석'!C19 | C10: =IFERROR(INDEX('기간별손익계산서(전년동기)'!$B:$B,MATCH(SUBSTITUTE("Ⅳ . 판 매 관 리 비"," ","")&"|1",'기간별손익계산서(전년동기)'!$P:$P,0)),0) | D10: =B10-C10 | E10: =IFERROR(IF(C10=0,"",(B10-C10)/ABS(C10)),"") | F10: ='매출액대비 비율분석'!F19 | G10: =B10-F10 | H10: =IFERROR(IF(F10=0,"",(B10-F10)/ABS(F10)),"")
A11: 영업이익 | B11: ='매출액대비 비율분석'!C41 | C11: =IFERROR(INDEX('기간별손익계산서(전년동기)'!$B:$B,MATCH(SUBSTITUTE("Ⅴ . 영 업 이 익"," ","")&"|1",'기간별손익계산서(전년동기)'!$P:$P,0)),0) | D11: =B11-C11 | E11: =IFERROR(IF(C11=0,"",(B11-C11)/ABS(C11)),"") | F11: ='매출액대비 비율분석'!F41 | G11: =B11-F11 | H11: =IFERROR(IF(F11=0,"",(B11-F11)/ABS(F11)),"")
A12: 영업외수익 | B12: ='매출액대비 비율분석'!C42 | C12: =IFERROR(INDEX('기간별손익계산서(전년동기)'!$B:$B,MATCH(SUBSTITUTE("Ⅵ . 영 업 외 수 익"," ","")&"|1",'기간별손익계산서(전년동기)'!$P:$P,0)),0) | D12: =B12-C12 | E12: =IFERROR(IF(C12=0,"",(B12-C12)/ABS(C12)),"") | F12: ='매출액대비 비율분석'!F42 | G12: =B12-F12 | H12: =IFERROR(IF(F12=0,"",(B12-F12)/ABS(F12)),"")
A13: 영업외비용 | B13: ='매출액대비 비율분석'!C50 | C13: =IFERROR(INDEX('기간별손익계산서(전년동기)'!$B:$B,MATCH(SUBSTITUTE("Ⅶ . 영 업 외 비 용"," ","")&"|1",'기간별손익계산서(전년동기)'!$P:$P,0)),0) | D13: =B13-C13 | E13: =IFERROR(IF(C13=0,"",(B13-C13)/ABS(C13)),"") | F13: ='매출액대비 비율분석'!F50 | G13: =B13-F13 | H13: =IFERROR(IF(F13=0,"",(B13-F13)/ABS(F13)),"")
A14: 법인세차감전순이익 | B14: ='매출액대비 비율분석'!C58 | C14: =IFERROR(INDEX('기간별손익계산서(전년동기)'!$B:$B,MATCH(SUBSTITUTE("Ⅷ . 법인세비용차감전순이익"," ","")&"|1",'기간별손익계산서(전년동기)'!$P:$P,0)),0) | D14: =B14-C14 | E14: =IFERROR(IF(C14=0,"",(B14-C14)/ABS(C14)),"") | F14: ='매출액대비 비율분석'!F58 | G14: =B14-F14 | H14: =IFERROR(IF(F14=0,"",(B14-F14)/ABS(F14)),"")
A15: 법인세비용 | B15: ='매출액대비 비율분석'!C59 | C15: =IFERROR(INDEX('기간별손익계산서(전년동기)'!$B:$B,MATCH(SUBSTITUTE("Ⅸ . 법 인 세 비 용"," ","")&"|1",'기간별손익계산서(전년동기)'!$P:$P,0)),0) | D15: =B15-C15 | E15: =IFERROR(IF(C15=0,"",(B15-C15)/ABS(C15)),"") | F15: ='매출액대비 비율분석'!F59 | G15: =B15-F15 | H15: =IFERROR(IF(F15=0,"",(B15-F15)/ABS(F15)),"")
A16: 당기순이익 | B16: ='매출액대비 비율분석'!C61 | C16: =IFERROR(INDEX('기간별손익계산서(전년동기)'!$B:$B,MATCH(SUBSTITUTE("Ⅹ . 당 기 순 이 익"," ","")&"|1",'기간별손익계산서(전년동기)'!$P:$P,0)),0) | D16: =B16-C16 | E16: =IFERROR(IF(C16=0,"",(B16-C16)/ABS(C16)),"") | F16: ='매출액대비 비율분석'!F61 | G16: =B16-F16 | H16: =IFERROR(IF(F16=0,"",(B16-F16)/ABS(F16)),"")
A17: 영업이익률(매출액대비) | B17: =IFERROR(B11/B7,"") | C17: =IFERROR(C11/C7,"") | F17: =IFERROR(F11/F7,"")
A18: 당기순이익률(매출액대비) | B18: =IFERROR(B16/B7,"") | C18: =IFERROR(C16/C7,"") | F18: =IFERROR(F16/F7,"")
A20: ■ 재무상태 요약 (단위: 천원)
A21: 구분 | B21: 당기 | C21: 전기 | D21: 증감액 | E21: 증감률
A22: 자산총계 | B22: =('재무상태표(내역)'!C50)+0 | C22: =('재무상태표(내역)'!F50)+0 | D22: =B22-C22 | E22: =IFERROR(IF(C22=0,"",(B22-C22)/ABS(C22)),"")
A23: 부채총계 | B23: =('재무상태표(내역)'!C65)+0 | C23: =('재무상태표(내역)'!F65)+0 | D23: =B23-C23 | E23: =IFERROR(IF(C23=0,"",(B23-C23)/ABS(C23)),"")
A24: 자본총계 | B24: =('재무상태표(내역)'!C79)+0 | C24: =('재무상태표(내역)'!F79)+0 | D24: =B24-C24 | E24: =IFERROR(IF(C24=0,"",(B24-C24)/ABS(C24)),"")
A25: 부채비율(부채/자본) | B25: =IFERROR(B23/B24,"") | C25: =IFERROR(C23/C24,"")
A27: ■ 월별 추이 (매출액 · 영업이익) (단위: 천원)
A28: 월 | B28: 매출액 | C28: 영업이익
A29: =IFERROR(MONTH(DATE(YEAR(인덱스!$K$1),1,1))&"월","") | B29: =IF(1<=MONTH(인덱스!$K$1),INDEX(기간별손익계산서!$C:$N,2,1),NA()) | C29: =IF(1<=MONTH(인덱스!$K$1),INDEX(기간별손익계산서!$C:$N,30,1),NA())
A30: =IFERROR(MONTH(DATE(YEAR(인덱스!$K$1),2,1))&"월","") | B30: =IF(2<=MONTH(인덱스!$K$1),INDEX(기간별손익계산서!$C:$N,2,2),NA()) | C30: =IF(2<=MONTH(인덱스!$K$1),INDEX(기간별손익계산서!$C:$N,30,2),NA())
A31: =IFERROR(MONTH(DATE(YEAR(인덱스!$K$1),3,1))&"월","") | B31: =IF(3<=MONTH(인덱스!$K$1),INDEX(기간별손익계산서!$C:$N,2,3),NA()) | C31: =IF(3<=MONTH(인덱스!$K$1),INDEX(기간별손익계산서!$C:$N,30,3),NA())
A32: =IFERROR(MONTH(DATE(YEAR(인덱스!$K$1),4,1))&"월","") | B32: =IF(4<=MONTH(인덱스!$K$1),INDEX(기간별손익계산서!$C:$N,2,4),NA()) | C32: =IF(4<=MONTH(인덱스!$K$1),INDEX(기간별손익계산서!$C:$N,30,4),NA())
A33: =IFERROR(MONTH(DATE(YEAR(인덱스!$K$1),5,1))&"월","") | B33: =IF(5<=MONTH(인덱스!$K$1),INDEX(기간별손익계산서!$C:$N,2,5),NA()) | C33: =IF(5<=MONTH(인덱스!$K$1),INDEX(기간별손익계산서!$C:$N,30,5),NA())
A34: =IFERROR(MONTH(DATE(YEAR(인덱스!$K$1),6,1))&"월","") | B34: =IF(6<=MONTH(인덱스!$K$1),INDEX(기간별손익계산서!$C:$N,2,6),NA()) | C34: =IF(6<=MONTH(인덱스!$K$1),INDEX(기간별손익계산서!$C:$N,30,6),NA())
A35: =IFERROR(MONTH(DATE(YEAR(인덱스!$K$1),7,1))&"월","") | B35: =IF(7<=MONTH(인덱스!$K$1),INDEX(기간별손익계산서!$C:$N,2,7),NA()) | C35: =IF(7<=MONTH(인덱스!$K$1),INDEX(기간별손익계산서!$C:$N,30,7),NA())
A36: =IFERROR(MONTH(DATE(YEAR(인덱스!$K$1),8,1))&"월","") | B36: =IF(8<=MONTH(인덱스!$K$1),INDEX(기간별손익계산서!$C:$N,2,8),NA()) | C36: =IF(8<=MONTH(인덱스!$K$1),INDEX(기간별손익계산서!$C:$N,30,8),NA())
A37: =IFERROR(MONTH(DATE(YEAR(인덱스!$K$1),9,1))&"월","") | B37: =IF(9<=MONTH(인덱스!$K$1),INDEX(기간별손익계산서!$C:$N,2,9),NA()) | C37: =IF(9<=MONTH(인덱스!$K$1),INDEX(기간별손익계산서!$C:$N,30,9),NA())
A38: =IFERROR(MONTH(DATE(YEAR(인덱스!$K$1),10,1))&"월","") | B38: =IF(10<=MONTH(인덱스!$K$1),INDEX(기간별손익계산서!$C:$N,2,10),NA()) | C38: =IF(10<=MONTH(인덱스!$K$1),INDEX(기간별손익계산서!$C:$N,30,10),NA())
A39: =IFERROR(MONTH(DATE(YEAR(인덱스!$K$1),11,1))&"월","") | B39: =IF(11<=MONTH(인덱스!$K$1),INDEX(기간별손익계산서!$C:$N,2,11),NA()) | C39: =IF(11<=MONTH(인덱스!$K$1),INDEX(기간별손익계산서!$C:$N,30,11),NA())
A40: =IFERROR(MONTH(DATE(YEAR(인덱스!$K$1),12,1))&"월","") | B40: =IF(12<=MONTH(인덱스!$K$1),INDEX(기간별손익계산서!$C:$N,2,12),NA()) | C40: =IF(12<=MONTH(인덱스!$K$1),INDEX(기간별손익계산서!$C:$N,30,12),NA())
A41: 총계 | B41: =_xlfn.AGGREGATE(9,6,B29:B40) | C41: =_xlfn.AGGREGATE(9,6,C29:C40)
A69: 특이사항 : 전년동기(1~7월) 영업외비용에 법인세추납액 3,800만원 포함(업무용승용차 비용 불인정 법인세 납부액)

Sheet 재무상태표(내역)
A1: 재 무 상 태 표
I2: =IF(ROUND(C50,0)=ROUND(C80,0),"대차검증(당기): 일치","대차검증(당기): 불일치 ⚠")
A3: ="(당기) "&TEXT(DATE(YEAR(인덱스!$K$1),1,1),"yyyy")&"년"&TEXT(MONTH(DATE(YEAR(인덱스!$K$1),1,1)),"00")&"월"&TEXT(DAY(DATE(YEAR(인덱스!$K$1),1,1)),"00")&"일"&" - "&TEXT(인덱스!$K$1,"yyyy")&"년"&TEXT(MONTH(인덱스!$K$1),"00")&"월"&TEXT(DAY(인덱스!$K$1),"00")&"일" | I3: =IF(ROUND(F50,0)=ROUND(F80,0),"대차검증(전기): 일치","대차검증(전기): 불일치 ⚠")
A4: ="(전기) "&TEXT(DATE(YEAR(인덱스!$K$1)-1,1,1),"yyyy")&"년"&TEXT(MONTH(DATE(YEAR(인덱스!$K$1)-1,1,1)),"00")&"월"&TEXT(DAY(DATE(YEAR(인덱스!$K$1)-1,1,1)),"00")&"일"&" - "&TEXT(DATE(YEAR(인덱스!$K$1)-1,12,31),"yyyy")&"년"&TEXT(MONTH(DATE(YEAR(인덱스!$K$1)-1,12,31)),"00")&"월"&TEXT(DAY(DATE(YEAR(인덱스!$K$1)-1,12,31)),"00")&"일"
A6: ㈜창현 | G6: 단위 : 원
A7: 과 목 | B7: 제 35 (당)기 | D7: 내역 | E7: 제 34 (전)기 | G7: 증감 | J7: 일치확인 | K7: 증감률
B8: 금 액 | E8: 금 액
A9: 자 산 | H9: =SUBSTITUTE(A9," ","") | I9: =H9&"|"&COUNTIF($H$9:H9,H9) | J9: =IF($A9="","",IF(ISNUMBER(MATCH($I9,재무상태표!$G:$G,0)),"✓ 일치","⚠ 확인필요")) | K9: =IFERROR(IF(F9=0,"",(C9-F9)/ABS(F9)),"")
A10: Ⅰ. 유 동 자 산 | B10: =IFERROR(INDEX(재무상태표!$B:$B,MATCH($I10,재무상태표!$G:$G,0)),0) | C10: =IFERROR(INDEX(재무상태표!$C:$C,MATCH($I10,재무상태표!$G:$G,0)),0) | E10: =IFERROR(INDEX(재무상태표!$D:$D,MATCH($I10,재무상태표!$G:$G,0)),0) | F10: =IFERROR(INDEX(재무상태표!$E:$E,MATCH($I10,재무상태표!$G:$G,0)),0) | G10: =C10-F10 | H10: =SUBSTITUTE(A10," ","") | I10: =H10&"|"&COUNTIF($H$9:H10,H10) | J10: =IF($A10="","",IF(ISNUMBER(MATCH($I10,재무상태표!$G:$G,0)),"✓ 일치","⚠ 확인필요")) | K10: =IFERROR(IF(F10=0,"",(C10-F10)/ABS(F10)),"")
A11: (1) 당 좌 자 산 | B11: =IFERROR(INDEX(재무상태표!$B:$B,MATCH($I11,재무상태표!$G:$G,0)),0) | C11: =IFERROR(INDEX(재무상태표!$C:$C,MATCH($I11,재무상태표!$G:$G,0)),0) | E11: =IFERROR(INDEX(재무상태표!$D:$D,MATCH($I11,재무상태표!$G:$G,0)),0) | F11: =IFERROR(INDEX(재무상태표!$E:$E,MATCH($I11,재무상태표!$G:$G,0)),0) | G11: =C11-F11 | H11: =SUBSTITUTE(A11," ","") | I11: =H11&"|"&COUNTIF($H$9:H11,H11) | J11: =IF($A11="","",IF(ISNUMBER(MATCH($I11,재무상태표!$G:$G,0)),"✓ 일치","⚠ 확인필요")) | K11: =IFERROR(IF(F11=0,"",(C11-F11)/ABS(F11)),"")
A12: 현 금 | B12: =IFERROR(INDEX(재무상태표!$B:$B,MATCH($I12,재무상태표!$G:$G,0)),0) | C12: =IFERROR(INDEX(재무상태표!$C:$C,MATCH($I12,재무상태표!$G:$G,0)),0) | E12: =IFERROR(INDEX(재무상태표!$D:$D,MATCH($I12,재무상태표!$G:$G,0)),0) | F12: =IFERROR(INDEX(재무상태표!$E:$E,MATCH($I12,재무상태표!$G:$G,0)),0) | G12: =C12-F12 | H12: =SUBSTITUTE(A12," ","") | I12: =H12&"|"&COUNTIF($H$9:H12,H12) | J12: =IF($A12="","",IF(ISNUMBER(MATCH($I12,재무상태표!$G:$G,0)),"✓ 일치","⚠ 확인필요")) | K12: =IFERROR(IF(F12=0,"",(C12-F12)/ABS(F12)),"")
A13: 보 통 예 금 | B13: =IFERROR(INDEX(재무상태표!$B:$B,MATCH($I13,재무상태표!$G:$G,0)),0) | C13: =IFERROR(INDEX(재무상태표!$C:$C,MATCH($I13,재무상태표!$G:$G,0)),0) | E13: =IFERROR(INDEX(재무상태표!$D:$D,MATCH($I13,재무상태표!$G:$G,0)),0) | F13: =IFERROR(INDEX(재무상태표!$E:$E,MATCH($I13,재무상태표!$G:$G,0)),0) | G13: =C13-F13 | H13: =SUBSTITUTE(A13," ","") | I13: =H13&"|"&COUNTIF($H$9:H13,H13) | J13: =IF($A13="","",IF(ISNUMBER(MATCH($I13,재무상태표!$G:$G,0)),"✓ 일치","⚠ 확인필요")) | K13: =IFERROR(IF(F13=0,"",(C13-F13)/ABS(F13)),"")
A14: 단 기 금 융 상 품 | B14: =IFERROR(INDEX(재무상태표!$B:$B,MATCH($I14,재무상태표!$G:$G,0)),0) | C14: =IFERROR(INDEX(재무상태표!$C:$C,MATCH($I14,재무상태표!$G:$G,0)),0) | E14: =IFERROR(INDEX(재무상태표!$D:$D,MATCH($I14,재무상태표!$G:$G,0)),0) | F14: =IFERROR(INDEX(재무상태표!$E:$E,MATCH($I14,재무상태표!$G:$G,0)),0) | G14: =C14-F14 | H14: =SUBSTITUTE(A14," ","") | I14: =H14&"|"&COUNTIF($H$9:H14,H14) | J14: =IF($A14="","",IF(ISNUMBER(MATCH($I14,재무상태표!$G:$G,0)),"✓ 일치","⚠ 확인필요")) | K14: =IFERROR(IF(F14=0,"",(C14-F14)/ABS(F14)),"")
A15: 외 화 보 통 예 금 | B15: =IFERROR(INDEX(재무상태표!$B:$B,MATCH($I15,재무상태표!$G:$G,0)),0) | C15: =IFERROR(INDEX(재무상태표!$C:$C,MATCH($I15,재무상태표!$G:$G,0)),0) | E15: =IFERROR(INDEX(재무상태표!$D:$D,MATCH($I15,재무상태표!$G:$G,0)),0) | F15: =IFERROR(INDEX(재무상태표!$E:$E,MATCH($I15,재무상태표!$G:$G,0)),0) | G15: =C15-F15 | H15: =SUBSTITUTE(A15," ","") | I15: =H15&"|"&COUNTIF($H$9:H15,H15) | J15: =IF($A15="","",IF(ISNUMBER(MATCH($I15,재무상태표!$G:$G,0)),"✓ 일치","⚠ 확인필요")) | K15: =IFERROR(IF(F15=0,"",(C15-F15)/ABS(F15)),"")
A16: 외 상 매 출 금 | B16: =IFERROR(INDEX(재무상태표!$B:$B,MATCH($I16,재무상태표!$G:$G,0)),0) | C16: =IFERROR(INDEX(재무상태표!$C:$C,MATCH($I16,재무상태표!$G:$G,0)),0) | E16: =IFERROR(INDEX(재무상태표!$D:$D,MATCH($I16,재무상태표!$G:$G,0)),0) | F16: =IFERROR(INDEX(재무상태표!$E:$E,MATCH($I16,재무상태표!$G:$G,0)),0) | G16: =B16-E16 | H16: =SUBSTITUTE(A16," ","") | I16: =H16&"|"&COUNTIF($H$9:H16,H16) | J16: =IF($A16="","",IF(ISNUMBER(MATCH($I16,재무상태표!$G:$G,0)),"✓ 일치","⚠ 확인필요")) | K16: =IFERROR(IF(F16=0,"",(C16-F16)/ABS(F16)),"")
A17: 대 손 충 당 금 | B17: =IFERROR(INDEX(재무상태표!$B:$B,MATCH($I17,재무상태표!$G:$G,0)),0) | C17: =IFERROR(INDEX(재무상태표!$C:$C,MATCH($I17,재무상태표!$G:$G,0)),0) | E17: =IFERROR(INDEX(재무상태표!$D:$D,MATCH($I17,재무상태표!$G:$G,0)),0) | F17: =IFERROR(INDEX(재무상태표!$E:$E,MATCH($I17,재무상태표!$G:$G,0)),0) | G17: =C17-F17 | H17: =SUBSTITUTE(A17," ","") | I17: =H17&"|"&COUNTIF($H$9:H17,H17) | J17: =IF($A17="","",IF(ISNUMBER(MATCH($I17,재무상태표!$G:$G,0)),"✓ 일치","⚠ 확인필요")) | K17: =IFERROR(IF(F17=0,"",(C17-F17)/ABS(F17)),"")
A18: 받 을 어 음 | B18: =IFERROR(INDEX(재무상태표!$B:$B,MATCH($I18,재무상태표!$G:$G,0)),0) | C18: =IFERROR(INDEX(재무상태표!$C:$C,MATCH($I18,재무상태표!$G:$G,0)),0) | E18: =IFERROR(INDEX(재무상태표!$D:$D,MATCH($I18,재무상태표!$G:$G,0)),0) | F18: =IFERROR(INDEX(재무상태표!$E:$E,MATCH($I18,재무상태표!$G:$G,0)),0) | G18: =C18-F18 | H18: =SUBSTITUTE(A18," ","") | I18: =H18&"|"&COUNTIF($H$9:H18,H18) | J18: =IF($A18="","",IF(ISNUMBER(MATCH($I18,재무상태표!$G:$G,0)),"✓ 일치","⚠ 확인필요")) | K18: =IFERROR(IF(F18=0,"",(C18-F18)/ABS(F18)),"")
A19: 대 손 충 당 금 | B19: =IFERROR(INDEX(재무상태표!$B:$B,MATCH($I19,재무상태표!$G:$G,0)),0) | C19: =IFERROR(INDEX(재무상태표!$C:$C,MATCH($I19,재무상태표!$G:$G,0)),0) | E19: =IFERROR(INDEX(재무상태표!$D:$D,MATCH($I19,재무상태표!$G:$G,0)),0) | F19: =IFERROR(INDEX(재무상태표!$E:$E,MATCH($I19,재무상태표!$G:$G,0)),0) | G19: =C19-F19 | H19: =SUBSTITUTE(A19," ","") | I19: =H19&"|"&COUNTIF($H$9:H19,H19) | J19: =IF($A19="","",IF(ISNUMBER(MATCH($I19,재무상태표!$G:$G,0)),"✓ 일치","⚠ 확인필요")) | K19: =IFERROR(IF(F19=0,"",(C19-F19)/ABS(F19)),"")
A20: 단 기 대 여 금 | B20: =IFERROR(INDEX(재무상태표!$B:$B,MATCH($I20,재무상태표!$G:$G,0)),0) | C20: =IFERROR(INDEX(재무상태표!$C:$C,MATCH($I20,재무상태표!$G:$G,0)),0) | E20: =IFERROR(INDEX(재무상태표!$D:$D,MATCH($I20,재무상태표!$G:$G,0)),0) | F20: =IFERROR(INDEX(재무상태표!$E:$E,MATCH($I20,재무상태표!$G:$G,0)),0) | G20: =C20-F20 | H20: =SUBSTITUTE(A20," ","") | I20: =H20&"|"&COUNTIF($H$9:H20,H20) | J20: =IF($A20="","",IF(ISNUMBER(MATCH($I20,재무상태표!$G:$G,0)),"✓ 일치","⚠ 확인필요")) | K20: =IFERROR(IF(F20=0,"",(C20-F20)/ABS(F20)),"")
A21: 미 수 수 익 | B21: =IFERROR(INDEX(재무상태표!$B:$B,MATCH($I21,재무상태표!$G:$G,0)),0) | C21: =IFERROR(INDEX(재무상태표!$C:$C,MATCH($I21,재무상태표!$G:$G,0)),0) | D21: 단기채권외 | E21: =IFERROR(INDEX(재무상태표!$D:$D,MATCH($I21,재무상태표!$G:$G,0)),0) | F21: =IFERROR(INDEX(재무상태표!$E:$E,MATCH($I21,재무상태표!$G:$G,0)),0) | G21: =C21-F21 | H21: =SUBSTITUTE(A21," ","") | I21: =H21&"|"&COUNTIF($H$9:H21,H21) | J21: =IF($A21="","",IF(ISNUMBER(MATCH($I21,재무상태표!$G:$G,0)),"✓ 일치","⚠ 확인필요")) | K21: =IFERROR(IF(F21=0,"",(C21-F21)/ABS(F21)),"")
A22: 미 수 금 | B22: =IFERROR(INDEX(재무상태표!$B:$B,MATCH($I22,재무상태표!$G:$G,0)),0) | C22: =IFERROR(INDEX(재무상태표!$C:$C,MATCH($I22,재무상태표!$G:$G,0)),0) | D22: 카드, 구매카드(KnS리테일) | E22: =IFERROR(INDEX(재무상태표!$D:$D,MATCH($I22,재무상태표!$G:$G,0)),0) | F22: =IFERROR(INDEX(재무상태표!$E:$E,MATCH($I22,재무상태표!$G:$G,0)),0) | G22: =C22-F22 | H22: =SUBSTITUTE(A22," ","") | I22: =H22&"|"&COUNTIF($H$9:H22,H22) | J22: =IF($A22="","",IF(ISNUMBER(MATCH($I22,재무상태표!$G:$G,0)),"✓ 일치","⚠ 확인필요")) | K22: =IFERROR(IF(F22=0,"",(C22-F22)/ABS(F22)),"")
A23: 선 급 금 | B23: =IFERROR(INDEX(재무상태표!$B:$B,MATCH($I23,재무상태표!$G:$G,0)),0) | C23: =IFERROR(INDEX(재무상태표!$C:$C,MATCH($I23,재무상태표!$G:$G,0)),0) | D23: 안현주유소(1백만) | E23: =IFERROR(INDEX(재무상태표!$D:$D,MATCH($I23,재무상태표!$G:$G,0)),0) | F23: =IFERROR(INDEX(재무상태표!$E:$E,MATCH($I23,재무상태표!$G:$G,0)),0) | G23: =C23-F23 | H23: =SUBSTITUTE(A23," ","") | I23: =H23&"|"&COUNTIF($H$9:H23,H23) | J23: =IF($A23="","",IF(ISNUMBER(MATCH($I23,재무상태표!$G:$G,0)),"✓ 일치","⚠ 확인필요")) | K23: =IFERROR(IF(F23=0,"",(C23-F23)/ABS(F23)),"")
A24: 선 급 비 용 | B24: =IFERROR(INDEX(재무상태표!$B:$B,MATCH($I24,재무상태표!$G:$G,0)),0) | C24: =IFERROR(INDEX(재무상태표!$C:$C,MATCH($I24,재무상태표!$G:$G,0)),0) | D24: KB,DB손해보험,삼성화재 | E24: =IFERROR(INDEX(재무상태표!$D:$D,MATCH($I24,재무상태표!$G:$G,0)),0) | F24: =IFERROR(INDEX(재무상태표!$E:$E,MATCH($I24,재무상태표!$G:$G,0)),0) | G24: =C24-F24 | H24: =SUBSTITUTE(A24," ","") | I24: =H24&"|"&COUNTIF($H$9:H24,H24) | J24: =IF($A24="","",IF(ISNUMBER(MATCH($I24,재무상태표!$G:$G,0)),"✓ 일치","⚠ 확인필요")) | K24: =IFERROR(IF(F24=0,"",(C24-F24)/ABS(F24)),"")
A25: 가 지 급 금 | B25: =IFERROR(INDEX(재무상태표!$B:$B,MATCH($I25,재무상태표!$G:$G,0)),0) | C25: =IFERROR(INDEX(재무상태표!$C:$C,MATCH($I25,재무상태표!$G:$G,0)),0) | D25: 단기대여 9억(윤인희), 차량과태료외 | E25: =IFERROR(INDEX(재무상태표!$D:$D,MATCH($I25,재무상태표!$G:$G,0)),0) | F25: =IFERROR(INDEX(재무상태표!$E:$E,MATCH($I25,재무상태표!$G:$G,0)),0) | G25: =C25-F25 | H25: =SUBSTITUTE(A25," ","") | I25: =H25&"|"&COUNTIF($H$9:H25,H25) | J25: =IF($A25="","",IF(ISNUMBER(MATCH($I25,재무상태표!$G:$G,0)),"✓ 일치","⚠ 확인필요")) | K25: =IFERROR(IF(F25=0,"",(C25-F25)/ABS(F25)),"")
A26: 부 가 세 대 급 금 | B26: =IFERROR(INDEX(재무상태표!$B:$B,MATCH($I26,재무상태표!$G:$G,0)),0) | C26: =IFERROR(INDEX(재무상태표!$C:$C,MATCH($I26,재무상태표!$G:$G,0)),0) | E26: =IFERROR(INDEX(재무상태표!$D:$D,MATCH($I26,재무상태표!$G:$G,0)),0) | F26: =IFERROR(INDEX(재무상태표!$E:$E,MATCH($I26,재무상태표!$G:$G,0)),0) | G26: =C26-F26 | H26: =SUBSTITUTE(A26," ","") | I26: =H26&"|"&COUNTIF($H$9:H26,H26) | J26: =IF($A26="","",IF(ISNUMBER(MATCH($I26,재무상태표!$G:$G,0)),"✓ 일치","⚠ 확인필요")) | K26: =IFERROR(IF(F26=0,"",(C26-F26)/ABS(F26)),"")
A27: 선 납 세 금 | B27: =IFERROR(INDEX(재무상태표!$B:$B,MATCH($I27,재무상태표!$G:$G,0)),0) | C27: =IFERROR(INDEX(재무상태표!$C:$C,MATCH($I27,재무상태표!$G:$G,0)),0) | D27: 금융투자상품 이자소득세외 | E27: =IFERROR(INDEX(재무상태표!$D:$D,MATCH($I27,재무상태표!$G:$G,0)),0) | F27: =IFERROR(INDEX(재무상태표!$E:$E,MATCH($I27,재무상태표!$G:$G,0)),0) | G27: =C27-F27 | H27: =SUBSTITUTE(A27," ","") | I27: =H27&"|"&COUNTIF($H$9:H27,H27) | J27: =IF($A27="","",IF(ISNUMBER(MATCH($I27,재무상태표!$G:$G,0)),"✓ 일치","⚠ 확인필요")) | K27: =IFERROR(IF(F27=0,"",(C27-F27)/ABS(F27)),"")
A28: (2) 재 고 자 산 | B28: =IFERROR(INDEX(재무상태표!$B:$B,MATCH($I28,재무상태표!$G:$G,0)),0) | C28: =IFERROR(INDEX(재무상태표!$C:$C,MATCH($I28,재무상태표!$G:$G,0)),0) | E28: =IFERROR(INDEX(재무상태표!$D:$D,MATCH($I28,재무상태표!$G:$G,0)),0) | F28: =IFERROR(INDEX(재무상태표!$E:$E,MATCH($I28,재무상태표!$G:$G,0)),0) | G28: =C28-F28 | H28: =SUBSTITUTE(A28," ","") | I28: =H28&"|"&COUNTIF($H$9:H28,H28) | J28: =IF($A28="","",IF(ISNUMBER(MATCH($I28,재무상태표!$G:$G,0)),"✓ 일치","⚠ 확인필요")) | K28: =IFERROR(IF(F28=0,"",(C28-F28)/ABS(F28)),"")
A29: 상 품 | B29: =IFERROR(INDEX(재무상태표!$B:$B,MATCH($I29,재무상태표!$G:$G,0)),0) | C29: =IFERROR(INDEX(재무상태표!$C:$C,MATCH($I29,재무상태표!$G:$G,0)),0) | E29: =IFERROR(INDEX(재무상태표!$D:$D,MATCH($I29,재무상태표!$G:$G,0)),0) | F29: =IFERROR(INDEX(재무상태표!$E:$E,MATCH($I29,재무상태표!$G:$G,0)),0) | G29: =C29-F29 | H29: =SUBSTITUTE(A29," ","") | I29: =H29&"|"&COUNTIF($H$9:H29,H29) | J29: =IF($A29="","",IF(ISNUMBER(MATCH($I29,재무상태표!$G:$G,0)),"✓ 일치","⚠ 확인필요")) | K29: =IFERROR(IF(F29=0,"",(C29-F29)/ABS(F29)),"")
A30: Ⅱ. 비 유 동 자 산 | B30: =IFERROR(INDEX(재무상태표!$B:$B,MATCH($I30,재무상태표!$G:$G,0)),0) | C30: =IFERROR(INDEX(재무상태표!$C:$C,MATCH($I30,재무상태표!$G:$G,0)),0) | E30: =IFERROR(INDEX(재무상태표!$D:$D,MATCH($I30,재무상태표!$G:$G,0)),0) | F30: =IFERROR(INDEX(재무상태표!$E:$E,MATCH($I30,재무상태표!$G:$G,0)),0) | G30: =C30-F30 | H30: =SUBSTITUTE(A30," ","") | I30: =H30&"|"&COUNTIF($H$9:H30,H30) | J30: =IF($A30="","",IF(ISNUMBER(MATCH($I30,재무상태표!$G:$G,0)),"✓ 일치","⚠ 확인필요")) | K30: =IFERROR(IF(F30=0,"",(C30-F30)/ABS(F30)),"")
A31: (1) 투 자 자 산 | B31: =IFERROR(INDEX(재무상태표!$B:$B,MATCH($I31,재무상태표!$G:$G,0)),0) | C31: =IFERROR(INDEX(재무상태표!$C:$C,MATCH($I31,재무상태표!$G:$G,0)),0) | E31: =IFERROR(INDEX(재무상태표!$D:$D,MATCH($I31,재무상태표!$G:$G,0)),0) | F31: =IFERROR(INDEX(재무상태표!$E:$E,MATCH($I31,재무상태표!$G:$G,0)),0) | G31: =C31-F31 | H31: =SUBSTITUTE(A31," ","") | I31: =H31&"|"&COUNTIF($H$9:H31,H31) | J31: =IF($A31="","",IF(ISNUMBER(MATCH($I31,재무상태표!$G:$G,0)),"✓ 일치","⚠ 확인필요")) | K31: =IFERROR(IF(F31=0,"",(C31-F31)/ABS(F31)),"")
A32: 매 도 가 능 증 권 | B32: =IFERROR(INDEX(재무상태표!$B:$B,MATCH($I32,재무상태표!$G:$G,0)),0) | C32: =IFERROR(INDEX(재무상태표!$C:$C,MATCH($I32,재무상태표!$G:$G,0)),0) | E32: =IFERROR(INDEX(재무상태표!$D:$D,MATCH($I32,재무상태표!$G:$G,0)),0) | F32: =IFERROR(INDEX(재무상태표!$E:$E,MATCH($I32,재무상태표!$G:$G,0)),0) | G32: =C32-F32 | H32: =SUBSTITUTE(A32," ","") | I32: =H32&"|"&COUNTIF($H$9:H32,H32) | J32: =IF($A32="","",IF(ISNUMBER(MATCH($I32,재무상태표!$G:$G,0)),"✓ 일치","⚠ 확인필요")) | K32: =IFERROR(IF(F32=0,"",(C32-F32)/ABS(F32)),"")
A33: (2) 유 형 자 산 | B33: =IFERROR(INDEX(재무상태표!$B:$B,MATCH($I33,재무상태표!$G:$G,0)),0) | C33: =IFERROR(INDEX(재무상태표!$C:$C,MATCH($I33,재무상태표!$G:$G,0)),0) | E33: =IFERROR(INDEX(재무상태표!$D:$D,MATCH($I33,재무상태표!$G:$G,0)),0) | F33: =IFERROR(INDEX(재무상태표!$E:$E,MATCH($I33,재무상태표!$G:$G,0)),0) | G33: =C33-F33 | H33: =SUBSTITUTE(A33," ","") | I33: =H33&"|"&COUNTIF($H$9:H33,H33) | J33: =IF($A33="","",IF(ISNUMBER(MATCH($I33,재무상태표!$G:$G,0)),"✓ 일치","⚠ 확인필요")) | K33: =IFERROR(IF(F33=0,"",(C33-F33)/ABS(F33)),"")
A34: 토 지 | B34: =IFERROR(INDEX(재무상태표!$B:$B,MATCH($I34,재무상태표!$G:$G,0)),0) | C34: =IFERROR(INDEX(재무상태표!$C:$C,MATCH($I34,재무상태표!$G:$G,0)),0) | E34: =IFERROR(INDEX(재무상태표!$D:$D,MATCH($I34,재무상태표!$G:$G,0)),0) | F34: =IFERROR(INDEX(재무상태표!$E:$E,MATCH($I34,재무상태표!$G:$G,0)),0) | G34: =C34-F34 | H34: =SUBSTITUTE(A34," ","") | I34: =H34&"|"&COUNTIF($H$9:H34,H34) | J34: =IF($A34="","",IF(ISNUMBER(MATCH($I34,재무상태표!$G:$G,0)),"✓ 일치","⚠ 확인필요")) | K34: =IFERROR(IF(F34=0,"",(C34-F34)/ABS(F34)),"")
A35: 건 물 | B35: =IFERROR(INDEX(재무상태표!$B:$B,MATCH($I35,재무상태표!$G:$G,0)),0) | C35: =IFERROR(INDEX(재무상태표!$C:$C,MATCH($I35,재무상태표!$G:$G,0)),0) | E35: =IFERROR(INDEX(재무상태표!$D:$D,MATCH($I35,재무상태표!$G:$G,0)),0) | F35: =IFERROR(INDEX(재무상태표!$E:$E,MATCH($I35,재무상태표!$G:$G,0)),0) | G35: =C35-F35 | H35: =SUBSTITUTE(A35," ","") | I35: =H35&"|"&COUNTIF($H$9:H35,H35) | J35: =IF($A35="","",IF(ISNUMBER(MATCH($I35,재무상태표!$G:$G,0)),"✓ 일치","⚠ 확인필요")) | K35: =IFERROR(IF(F35=0,"",(C35-F35)/ABS(F35)),"")
A36: 감가 상각 누 계 액 | B36: =IFERROR(INDEX(재무상태표!$B:$B,MATCH($I36,재무상태표!$G:$G,0)),0) | C36: =IFERROR(INDEX(재무상태표!$C:$C,MATCH($I36,재무상태표!$G:$G,0)),0) | E36: =IFERROR(INDEX(재무상태표!$D:$D,MATCH($I36,재무상태표!$G:$G,0)),0) | F36: =IFERROR(INDEX(재무상태표!$E:$E,MATCH($I36,재무상태표!$G:$G,0)),0) | G36: =C36-F36 | H36: =SUBSTITUTE(A36," ","") | I36: =H36&"|"&COUNTIF($H$9:H36,H36) | J36: =IF($A36="","",IF(ISNUMBER(MATCH($I36,재무상태표!$G:$G,0)),"✓ 일치","⚠ 확인필요")) | K36: =IFERROR(IF(F36=0,"",(C36-F36)/ABS(F36)),"")
A37: 기 계 장 치 | B37: =IFERROR(INDEX(재무상태표!$B:$B,MATCH($I37,재무상태표!$G:$G,0)),0) | C37: =IFERROR(INDEX(재무상태표!$C:$C,MATCH($I37,재무상태표!$G:$G,0)),0) | E37: =IFERROR(INDEX(재무상태표!$D:$D,MATCH($I37,재무상태표!$G:$G,0)),0) | F37: =IFERROR(INDEX(재무상태표!$E:$E,MATCH($I37,재무상태표!$G:$G,0)),0) | G37: =C37-F37 | H37: =SUBSTITUTE(A37," ","") | I37: =H37&"|"&COUNTIF($H$9:H37,H37) | J37: =IF($A37="","",IF(ISNUMBER(MATCH($I37,재무상태표!$G:$G,0)),"✓ 일치","⚠ 확인필요")) | K37: =IFERROR(IF(F37=0,"",(C37-F37)/ABS(F37)),"")
A38: 감가 상각 누 계 액 | B38: =IFERROR(INDEX(재무상태표!$B:$B,MATCH($I38,재무상태표!$G:$G,0)),0) | C38: =IFERROR(INDEX(재무상태표!$C:$C,MATCH($I38,재무상태표!$G:$G,0)),0) | E38: =IFERROR(INDEX(재무상태표!$D:$D,MATCH($I38,재무상태표!$G:$G,0)),0) | F38: =IFERROR(INDEX(재무상태표!$E:$E,MATCH($I38,재무상태표!$G:$G,0)),0) | G38: =C38-F38 | H38: =SUBSTITUTE(A38," ","") | I38: =H38&"|"&COUNTIF($H$9:H38,H38) | J38: =IF($A38="","",IF(ISNUMBER(MATCH($I38,재무상태표!$G:$G,0)),"✓ 일치","⚠ 확인필요")) | K38: =IFERROR(IF(F38=0,"",(C38-F38)/ABS(F38)),"")
A39: 차 량 운 반 구 | B39: =IFERROR(INDEX(재무상태표!$B:$B,MATCH($I39,재무상태표!$G:$G,0)),0) | C39: =IFERROR(INDEX(재무상태표!$C:$C,MATCH($I39,재무상태표!$G:$G,0)),0) | E39: =IFERROR(INDEX(재무상태표!$D:$D,MATCH($I39,재무상태표!$G:$G,0)),0) | F39: =IFERROR(INDEX(재무상태표!$E:$E,MATCH($I39,재무상태표!$G:$G,0)),0) | G39: =C39-F39 | H39: =SUBSTITUTE(A39," ","") | I39: =H39&"|"&COUNTIF($H$9:H39,H39) | J39: =IF($A39="","",IF(ISNUMBER(MATCH($I39,재무상태표!$G:$G,0)),"✓ 일치","⚠ 확인필요")) | K39: =IFERROR(IF(F39=0,"",(C39-F39)/ABS(F39)),"")
... A46: 대 손 충 당 금 | B46: =IFERROR(INDEX(재무상태표!$B:$B,MATCH($I46,재무상태표!$G:$G,0)),0) | C46: =IFERROR(INDEX(재무상태표!$C:$C,MATCH($I46,재무상태표!$G:$G,0)),0) | E46: =IFERROR(INDEX(재무상태표!$D:$D,MATCH($I46,재무상태표!$G:$G,0)),0) | F46: =IFERROR(INDEX(재무상태표!$E:$E,MATCH($I46,재무상태표!$G:$G,0)),0) | G46: =C46-F46 | H46: =SUBSTITUTE(A46," ","") | I46: =H46&"|"&COUNTIF($H$9:H46,H46) | J46: =IF($A46="","",IF(ISNUMBER(MATCH($I46,재무상태표!$G:$G,0)),"✓ 일치","⚠ 확인필요")) | K46: =IFERROR(IF(F46=0,"",(C46-F46)/ABS(F46)),"")
A47: 임 차 보 증 금 | B47: =IFERROR(INDEX(재무상태표!$B:$B,MATCH($I47,재무상태표!$G:$G,0)),0) | C47: =IFERROR(INDEX(재무상태표!$C:$C,MATCH($I47,재무상태표!$G:$G,0)),0) | D47: 강북 6천,강서 4.5천,영남 3천,본사 5백만 | E47: =IFERROR(INDEX(재무상태표!$D:$D,MATCH($I47,재무상태표!$G:$G,0)),0) | F47: =IFERROR(INDEX(재무상태표!$E:$E,MATCH($I47,재무상태표!$G:$G,0)),0) | G47: =C47-F47 | H47: =SUBSTITUTE(A47," ","") | I47: =H47&"|"&COUNTIF($H$9:H47,H47) | J47: =IF($A47="","",IF(ISNUMBER(MATCH($I47,재무상태표!$G:$G,0)),"✓ 일치","⚠ 확인필요")) | K47: =IFERROR(IF(F47=0,"",(C47-F47)/ABS(F47)),"")
...

Sheet 매출액대비 비율분석
A1: 손익계산서(매출액대비 비율분석)
A3: ="(당기) "&TEXT(DATE(YEAR(인덱스!$K$1),1,1),"yyyy")&"년"&TEXT(MONTH(DATE(YEAR(인덱스!$K$1),1,1)),"00")&"월"&TEXT(DAY(DATE(YEAR(인덱스!$K$1),1,1)),"00")&"일"&" - "&TEXT(인덱스!$K$1,"yyyy")&"년"&TEXT(MONTH(인덱스!$K$1),"00")&"월"&TEXT(DAY(인덱스!$K$1),"00")&"일"
A4: ="(전기) "&TEXT(DATE(YEAR(인덱스!$K$1)-1,1,1),"yyyy")&"년"&TEXT(MONTH(DATE(YEAR(인덱스!$K$1)-1,1,1)),"00")&"월"&TEXT(DAY(DATE(YEAR(인덱스!$K$1)-1,1,1)),"00")&"일"&" - "&TEXT(DATE(YEAR(인덱스!$K$1)-1,12,31),"yyyy")&"년"&TEXT(MONTH(DATE(YEAR(인덱스!$K$1)-1,12,31)),"00")&"월"&TEXT(DAY(DATE(YEAR(인덱스!$K$1)-1,12,31)),"00")&"일"
A6: ㈜창현 | G6: 단위 : 원
A7: 과 목 | B7: 제 35 (당)기 | D7: 매출액대비 비율 | E7: 제 34 (전)기 | G7: 매출액대비 비율 | J7: 일치확인 | K7: 비율증감(%p)
B8: 금 액 | E8: 금 액
A9: Ⅰ . 매 출 액 | B9: =IFERROR(INDEX(손익계산서!$B:$B,MATCH($I9,손익계산서!$G:$G,0)),0) | C9: =IFERROR(INDEX(손익계산서!$C:$C,MATCH($I9,손익계산서!$G:$G,0)),0) | D9: =C9/C9 | E9: =IFERROR(INDEX(손익계산서!$D:$D,MATCH($I9,손익계산서!$G:$G,0)),0) | F9: =IFERROR(INDEX(손익계산서!$E:$E,MATCH($I9,손익계산서!$G:$G,0)),0) | G9: =F9/F9 | H9: =SUBSTITUTE(A9," ","") | I9: =H9&"|"&COUNTIF($H$9:H9,H9) | J9: =IF($A9="","",IF(ISNUMBER(MATCH($I9,손익계산서!$G:$G,0)),"✓ 일치","⚠ 확인필요")) | K9: =IFERROR(IF(OR(D9="",G9=""),"",D9-G9),"")
A10: 상 품 매 출 | B10: =IFERROR(INDEX(손익계산서!$B:$B,MATCH($I10,손익계산서!$G:$G,0)),0) | C10: =IFERROR(INDEX(손익계산서!$C:$C,MATCH($I10,손익계산서!$G:$G,0)),0) | E10: =IFERROR(INDEX(손익계산서!$D:$D,MATCH($I10,손익계산서!$G:$G,0)),0) | F10: =IFERROR(INDEX(손익계산서!$E:$E,MATCH($I10,손익계산서!$G:$G,0)),0) | H10: =SUBSTITUTE(A10," ","") | I10: =H10&"|"&COUNTIF($H$9:H10,H10) | J10: =IF($A10="","",IF(ISNUMBER(MATCH($I10,손익계산서!$G:$G,0)),"✓ 일치","⚠ 확인필요")) | K10: =IFERROR(IF(OR(D10="",G10=""),"",D10-G10),"")
A11: 상 품 수 출 매 출 | B11: =IFERROR(INDEX(손익계산서!$B:$B,MATCH($I11,손익계산서!$G:$G,0)),0) | C11: =IFERROR(INDEX(손익계산서!$C:$C,MATCH($I11,손익계산서!$G:$G,0)),0) | E11: =IFERROR(INDEX(손익계산서!$D:$D,MATCH($I11,손익계산서!$G:$G,0)),0) | F11: =IFERROR(INDEX(손익계산서!$E:$E,MATCH($I11,손익계산서!$G:$G,0)),0) | H11: =SUBSTITUTE(A11," ","") | I11: =H11&"|"&COUNTIF($H$9:H11,H11) | J11: =IF($A11="","",IF(ISNUMBER(MATCH($I11,손익계산서!$G:$G,0)),"✓ 일치","⚠ 확인필요")) | K11: =IFERROR(IF(OR(D11="",G11=""),"",D11-G11),"")
A12: Ⅱ . 매 출 원 가 | B12: =IFERROR(INDEX(손익계산서!$B:$B,MATCH($I12,손익계산서!$G:$G,0)),0) | C12: =IFERROR(INDEX(손익계산서!$C:$C,MATCH($I12,손익계산서!$G:$G,0)),0) | D12: =C12/C9 | E12: =IFERROR(INDEX(손익계산서!$D:$D,MATCH($I12,손익계산서!$G:$G,0)),0) | F12: =IFERROR(INDEX(손익계산서!$E:$E,MATCH($I12,손익계산서!$G:$G,0)),0) | G12: =F12/F9 | H12: =SUBSTITUTE(A12," ","") | I12: =H12&"|"&COUNTIF($H$9:H12,H12) | J12: =IF($A12="","",IF(ISNUMBER(MATCH($I12,손익계산서!$G:$G,0)),"✓ 일치","⚠ 확인필요")) | K12: =IFERROR(IF(OR(D12="",G12=""),"",D12-G12),"")
A13: 상 품 매 출 원 가 | B13: =IFERROR(INDEX(손익계산서!$B:$B,MATCH($I13,손익계산서!$G:$G,0)),0) | C13: =IFERROR(INDEX(손익계산서!$C:$C,MATCH($I13,손익계산서!$G:$G,0)),0) | E13: =IFERROR(INDEX(손익계산서!$D:$D,MATCH($I13,손익계산서!$G:$G,0)),0) | F13: =IFERROR(INDEX(손익계산서!$E:$E,MATCH($I13,손익계산서!$G:$G,0)),0) | H13: =SUBSTITUTE(A13," ","") | I13: =H13&"|"&COUNTIF($H$9:H13,H13) | J13: =IF($A13="","",IF(ISNUMBER(MATCH($I13,손익계산서!$G:$G,0)),"✓ 일치","⚠ 확인필요")) | K13: =IFERROR(IF(OR(D13="",G13=""),"",D13-G13),"")
A14: 기초 상품 재고액 | B14: =IFERROR(INDEX(손익계산서!$B:$B,MATCH($I14,손익계산서!$G:$G,0)),0) | C14: =IFERROR(INDEX(손익계산서!$C:$C,MATCH($I14,손익계산서!$G:$G,0)),0) | E14: =IFERROR(INDEX(손익계산서!$D:$D,MATCH($I14,손익계산서!$G:$G,0)),0) | F14: =IFERROR(INDEX(손익계산서!$E:$E,MATCH($I14,손익계산서!$G:$G,0)),0) | H14: =SUBSTITUTE(A14," ","") | I14: =H14&"|"&COUNTIF($H$9:H14,H14) | J14: =IF($A14="","",IF(ISNUMBER(MATCH($I14,손익계산서!$G:$G,0)),"✓ 일치","⚠ 확인필요")) | K14: =IFERROR(IF(OR(D14="",G14=""),"",D14-G14),"")
A15: 당기 상품 매 입 액 | B15: =IFERROR(INDEX(손익계산서!$B:$B,MATCH($I15,손익계산서!$G:$G,0)),0) | C15: =IFERROR(INDEX(손익계산서!$C:$C,MATCH($I15,손익계산서!$G:$G,0)),0) | E15: =IFERROR(INDEX(손익계산서!$D:$D,MATCH($I15,손익계산서!$G:$G,0)),0) | F15: =IFERROR(INDEX(손익계산서!$E:$E,MATCH($I15,손익계산서!$G:$G,0)),0) | H15: =SUBSTITUTE(A15," ","") | I15: =H15&"|"&COUNTIF($H$9:H15,H15) | J15: =IF($A15="","",IF(ISNUMBER(MATCH($I15,손익계산서!$G:$G,0)),"✓ 일치","⚠ 확인필요")) | K15: =IFERROR(IF(OR(D15="",G15=""),"",D15-G15),"")
A16: 매 입 할 인 | B16: =IFERROR(INDEX(손익계산서!$B:$B,MATCH($I16,손익계산서!$G:$G,0)),0) | C16: =IFERROR(INDEX(손익계산서!$C:$C,MATCH($I16,손익계산서!$G:$G,0)),0) | E16: =IFERROR(INDEX(손익계산서!$D:$D,MATCH($I16,손익계산서!$G:$G,0)),0) | F16: =IFERROR(INDEX(손익계산서!$E:$E,MATCH($I16,손익계산서!$G:$G,0)),0) | H16: =SUBSTITUTE(A16," ","") | I16: =H16&"|"&COUNTIF($H$9:H16,H16) | J16: =IF($A16="","",IF(ISNUMBER(MATCH($I16,손익계산서!$G:$G,0)),"✓ 일치","⚠ 확인필요")) | K16: =IFERROR(IF(OR(D16="",G16=""),"",D16-G16),"")
A17: 기말 상품 재고액 | B17: =IFERROR(INDEX(손익계산서!$B:$B,MATCH($I17,손익계산서!$G:$G,0)),0) | C17: =IFERROR(INDEX(손익계산서!$C:$C,MATCH($I17,손익계산서!$G:$G,0)),0) | E17: =IFERROR(INDEX(손익계산서!$D:$D,MATCH($I17,손익계산서!$G:$G,0)),0) | F17: =IFERROR(INDEX(손익계산서!$E:$E,MATCH($I17,손익계산서!$G:$G,0)),0) | H17: =SUBSTITUTE(A17," ","") | I17: =H17&"|"&COUNTIF($H$9:H17,H17) | J17: =IF($A17="","",IF(ISNUMBER(MATCH($I17,손익계산서!$G:$G,0)),"✓ 일치","⚠ 확인필요")) | K17: =IFERROR(IF(OR(D17="",G17=""),"",D17-G17),"")
A18: Ⅲ . 매 출 총 이 익 | B18: =IFERROR(INDEX(손익계산서!$B:$B,MATCH($I18,손익계산서!$G:$G,0)),0) | C18: =IFERROR(INDEX(손익계산서!$C:$C,MATCH($I18,손익계산서!$G:$G,0)),0) | D18: =C18/C9 | E18: =IFERROR(INDEX(손익계산서!$D:$D,MATCH($I18,손익계산서!$G:$G,0)),0) | F18: =IFERROR(INDEX(손익계산서!$E:$E,MATCH($I18,손익계산서!$G:$G,0)),0) | G18: =F18/F9 | H18: =SUBSTITUTE(A18," ","") | I18: =H18&"|"&COUNTIF($H$9:H18,H18) | J18: =IF($A18="","",IF(ISNUMBER(MATCH($I18,손익계산서!$G:$G,0)),"✓ 일치","⚠ 확인필요")) | K18: =IFERROR(IF(OR(D18="",G18=""),"",D18-G18),"")
A19: Ⅳ . 판 매 관 리 비 | B19: =IFERROR(INDEX(손익계산서!$B:$B,MATCH($I19,손익계산서!$G:$G,0)),0) | C19: =IFERROR(INDEX(손익계산서!$C:$C,MATCH($I19,손익계산서!$G:$G,0)),0) | D19: =C19/C9 | E19: =IFERROR(INDEX(손익계산서!$D:$D,MATCH($I19,손익계산서!$G:$G,0)),0) | F19: =IFERROR(INDEX(손익계산서!$E:$E,MATCH($I19,손익계산서!$G:$G,0)),0) | G19: =F19/F9 | H19: =SUBSTITUTE(A19," ","") | I19: =H19&"|"&COUNTIF($H$9:H19,H19) | J19: =IF($A19="","",IF(ISNUMBER(MATCH($I19,손익계산서!$G:$G,0)),"✓ 일치","⚠ 확인필요")) | K19: =IFERROR(IF(OR(D19="",G19=""),"",D19-G19),"") | M19: 판관비대비 비율
A20: 직 원 급 여 | B20: =IFERROR(INDEX(손익계산서!$B:$B,MATCH($I20,손익계산서!$G:$G,0)),0) | C20: =IFERROR(INDEX(손익계산서!$C:$C,MATCH($I20,손익계산서!$G:$G,0)),0) | D20: =B20/$C$9 | E20: =IFERROR(INDEX(손익계산서!$D:$D,MATCH($I20,손익계산서!$G:$G,0)),0) | F20: =IFERROR(INDEX(손익계산서!$E:$E,MATCH($I20,손익계산서!$G:$G,0)),0) | G20: =E20/F$9 | H20: =SUBSTITUTE(A20," ","") | I20: =H20&"|"&COUNTIF($H$9:H20,H20) | J20: =IF($A20="","",IF(ISNUMBER(MATCH($I20,손익계산서!$G:$G,0)),"✓ 일치","⚠ 확인필요")) | K20: =IFERROR(IF(OR(D20="",G20=""),"",D20-G20),"") | M20: =(B20/$C$19) | P20: =(E20/$F$19)
A21: 잡 급 | B21: =IFERROR(INDEX(손익계산서!$B:$B,MATCH($I21,손익계산서!$G:$G,0)),0) | C21: =IFERROR(INDEX(손익계산서!$C:$C,MATCH($I21,손익계산서!$G:$G,0)),0) | D21: =B21/$C$9 | E21: =IFERROR(INDEX(손익계산서!$D:$D,MATCH($I21,손익계산서!$G:$G,0)),0) | F21: =IFERROR(INDEX(손익계산서!$E:$E,MATCH($I21,손익계산서!$G:$G,0)),0) | G21: =E21/F$9 | H21: =SUBSTITUTE(A21," ","") | I21: =H21&"|"&COUNTIF($H$9:H21,H21) | J21: =IF($A21="","",IF(ISNUMBER(MATCH($I21,손익계산서!$G:$G,0)),"✓ 일치","⚠ 확인필요")) | K21: =IFERROR(IF(OR(D21="",G21=""),"",D21-G21),"") | M21: =(B21/$C$19) | P21: =(E21/$F$19)
A22: 상 여 금 | B22: =IFERROR(INDEX(손익계산서!$B:$B,MATCH($I22,손익계산서!$G:$G,0)),0) | C22: =IFERROR(INDEX(손익계산서!$C:$C,MATCH($I22,손익계산서!$G:$G,0)),0) | D22: =B22/$C$9 | E22: =IFERROR(INDEX(손익계산서!$D:$D,MATCH($I22,손익계산서!$G:$G,0)),0) | F22: =IFERROR(INDEX(손익계산서!$E:$E,MATCH($I22,손익계산서!$G:$G,0)),0) | G22: =E22/F$9 | H22: =SUBSTITUTE(A22," ","") | I22: =H22&"|"&COUNTIF($H$9:H22,H22) | J22: =IF($A22="","",IF(ISNUMBER(MATCH($I22,손익계산서!$G:$G,0)),"✓ 일치","⚠ 확인필요")) | K22: =IFERROR(IF(OR(D22="",G22=""),"",D22-G22),"") | M22: =(B22/$C$19) | P22: =(E22/$F$19)
A23: 연 차 수 당 | B23: =IFERROR(INDEX(손익계산서!$B:$B,MATCH($I23,손익계산서!$G:$G,0)),0) | C23: =IFERROR(INDEX(손익계산서!$C:$C,MATCH($I23,손익계산서!$G:$G,0)),0) | D23: =B23/$C$9 | E23: =IFERROR(INDEX(손익계산서!$D:$D,MATCH($I23,손익계산서!$G:$G,0)),0) | F23: =IFERROR(INDEX(손익계산서!$E:$E,MATCH($I23,손익계산서!$G:$G,0)),0) | G23: =E23/F$9 | H23: =SUBSTITUTE(A23," ","") | I23: =H23&"|"&COUNTIF($H$9:H23,H23) | J23: =IF($A23="","",IF(ISNUMBER(MATCH($I23,손익계산서!$G:$G,0)),"✓ 일치","⚠ 확인필요")) | K23: =IFERROR(IF(OR(D23="",G23=""),"",D23-G23),"") | M23: =(B23/$C$19) | P23: =(E23/$F$19)
A24: 퇴 직 급 여 | B24: =IFERROR(INDEX(손익계산서!$B:$B,MATCH($I24,손익계산서!$G:$G,0)),0) | C24: =IFERROR(INDEX(손익계산서!$C:$C,MATCH($I24,손익계산서!$G:$G,0)),0) | D24: =B24/$C$9 | E24: =IFERROR(INDEX(손익계산서!$D:$D,MATCH($I24,손익계산서!$G:$G,0)),0) | F24: =IFERROR(INDEX(손익계산서!$E:$E,MATCH($I24,손익계산서!$G:$G,0)),0) | G24: =E24/F$9 | H24: =SUBSTITUTE(A24," ","") | I24: =H24&"|"&COUNTIF($H$9:H24,H24) | J24: =IF($A24="","",IF(ISNUMBER(MATCH($I24,손익계산서!$G:$G,0)),"✓ 일치","⚠ 확인필요")) | K24: =IFERROR(IF(OR(D24="",G24=""),"",D24-G24),"") | M24: =(B24/$C$19) | P24: =(E24/$F$19)
A25: 복 리 후 생 비 | B25: =IFERROR(INDEX(손익계산서!$B:$B,MATCH($I25,손익계산서!$G:$G,0)),0) | C25: =IFERROR(INDEX(손익계산서!$C:$C,MATCH($I25,손익계산서!$G:$G,0)),0) | D25: =B25/$C$9 | E25: =IFERROR(INDEX(손익계산서!$D:$D,MATCH($I25,손익계산서!$G:$G,0)),0) | F25: =IFERROR(INDEX(손익계산서!$E:$E,MATCH($I25,손익계산서!$G:$G,0)),0) | G25: =E25/F$9 | H25: =SUBSTITUTE(A25," ","") | I25: =H25&"|"&COUNTIF($H$9:H25,H25) | J25: =IF($A25="","",IF(ISNUMBER(MATCH($I25,손익계산서!$G:$G,0)),"✓ 일치","⚠ 확인필요")) | K25: =IFERROR(IF(OR(D25="",G25=""),"",D25-G25),"") | M25: =(B25/$C$19) | P25: =(E25/$F$19)
A26: 여 비 교 통 비 | B26: =IFERROR(INDEX(손익계산서!$B:$B,MATCH($I26,손익계산서!$G:$G,0)),0) | C26: =IFERROR(INDEX(손익계산서!$C:$C,MATCH($I26,손익계산서!$G:$G,0)),0) | D26: =B26/$C$9 | E26: =IFERROR(INDEX(손익계산서!$D:$D,MATCH($I26,손익계산서!$G:$G,0)),0) | F26: =IFERROR(INDEX(손익계산서!$E:$E,MATCH($I26,손익계산서!$G:$G,0)),0) | G26: =E26/F$9 | H26: =SUBSTITUTE(A26," ","") | I26: =H26&"|"&COUNTIF($H$9:H26,H26) | J26: =IF($A26="","",IF(ISNUMBER(MATCH($I26,손익계산서!$G:$G,0)),"✓ 일치","⚠ 확인필요")) | K26: =IFERROR(IF(OR(D26="",G26=""),"",D26-G26),"") | M26: =(B26/$C$19) | P26: =(E26/$F$19)
A27: 접 대 비 | B27: =IFERROR(INDEX(손익계산서!$B:$B,MATCH($I27,손익계산서!$G:$G,0)),0) | C27: =IFERROR(INDEX(손익계산서!$C:$C,MATCH($I27,손익계산서!$G:$G,0)),0) | D27: =B27/$C$9 | E27: =IFERROR(INDEX(손익계산서!$D:$D,MATCH($I27,손익계산서!$G:$G,0)),0) | F27: =IFERROR(INDEX(손익계산서!$E:$E,MATCH($I27,손익계산서!$G:$G,0)),0) | G27: =E27/F$9 | H27: =SUBSTITUTE(A27," ","") | I27: =H27&"|"&COUNTIF($H$9:H27,H27) | J27: =IF($A27="","",IF(ISNUMBER(MATCH($I27,손익계산서!$G:$G,0)),"✓ 일치","⚠ 확인필요")) | K27: =IFERROR(IF(OR(D27="",G27=""),"",D27-G27),"") | M27: =(B27/$C$19) | P27: =(E27/$F$19)
A28: 통 신 비 | B28: =IFERROR(INDEX(손익계산서!$B:$B,MATCH($I28,손익계산서!$G:$G,0)),0) | C28: =IFERROR(INDEX(손익계산서!$C:$C,MATCH($I28,손익계산서!$G:$G,0)),0) | D28: =B28/$C$9 | E28: =IFERROR(INDEX(손익계산서!$D:$D,MATCH($I28,손익계산서!$G:$G,0)),0) | F28: =IFERROR(INDEX(손익계산서!$E:$E,MATCH($I28,손익계산서!$G:$G,0)),0) | G28: =E28/F$9 | H28: =SUBSTITUTE(A28," ","") | I28: =H28&"|"&COUNTIF($H$9:H28,H28) | J28: =IF($A28="","",IF(ISNUMBER(MATCH($I28,손익계산서!$G:$G,0)),"✓ 일치","⚠ 확인필요")) | K28: =IFERROR(IF(OR(D28="",G28=""),"",D28-G28),"") | M28: =(B28/$C$19) | P28: =(E28/$F$19)
A29: 수 도 광 열 비 | B29: =IFERROR(INDEX(손익계산서!$B:$B,MATCH($I29,손익계산서!$G:$G,0)),0) | C29: =IFERROR(INDEX(손익계산서!$C:$C,MATCH($I29,손익계산서!$G:$G,0)),0) | D29: =B29/$C$9 | E29: =IFERROR(INDEX(손익계산서!$D:$D,MATCH($I29,손익계산서!$G:$G,0)),0) | F29: =IFERROR(INDEX(손익계산서!$E:$E,MATCH($I29,손익계산서!$G:$G,0)),0) | G29: =E29/F$9 | H29: =SUBSTITUTE(A29," ","") | I29: =H29&"|"&COUNTIF($H$9:H29,H29) | J29: =IF($A29="","",IF(ISNUMBER(MATCH($I29,손익계산서!$G:$G,0)),"✓ 일치","⚠ 확인필요")) | K29: =IFERROR(IF(OR(D29="",G29=""),"",D29-G29),"") | M29: =(B29/$C$19) | P29: =(E29/$F$19)
A30: 전 력 비 | B30: =IFERROR(INDEX(손익계산서!$B:$B,MATCH($I30,손익계산서!$G:$G,0)),0) | C30: =IFERROR(INDEX(손익계산서!$C:$C,MATCH($I30,손익계산서!$G:$G,0)),0) | D30: =B30/$C$9 | E30: =IFERROR(INDEX(손익계산서!$D:$D,MATCH($I30,손익계산서!$G:$G,0)),0) | F30: =IFERROR(INDEX(손익계산서!$E:$E,MATCH($I30,손익계산서!$G:$G,0)),0) | G30: =E30/F$9 | H30: =SUBSTITUTE(A30," ","") | I30: =H30&"|"&COUNTIF($H$9:H30,H30) | J30: =IF($A30="","",IF(ISNUMBER(MATCH($I30,손익계산서!$G:$G,0)),"✓ 일치","⚠ 확인필요")) | K30: =IFERROR(IF(OR(D30="",G30=""),"",D30-G30),"") | M30: =(B30/$C$19) | P30: =(E30/$F$19)
A31: 세 금 과 공 과 금 | B31: =IFERROR(INDEX(손익계산서!$B:$B,MATCH($I31,손익계산서!$G:$G,0)),0) | C31: =IFERROR(INDEX(손익계산서!$C:$C,MATCH($I31,손익계산서!$G:$G,0)),0) | D31: =B31/$C$9 | E31: =IFERROR(INDEX(손익계산서!$D:$D,MATCH($I31,손익계산서!$G:$G,0)),0) | F31: =IFERROR(INDEX(손익계산서!$E:$E,MATCH($I31,손익계산서!$G:$G,0)),0) | G31: =E31/F$9 | H31: =SUBSTITUTE(A31," ","") | I31: =H31&"|"&COUNTIF($H$9:H31,H31) | J31: =IF($A31="","",IF(ISNUMBER(MATCH($I31,손익계산서!$G:$G,0)),"✓ 일치","⚠ 확인필요")) | K31: =IFERROR(IF(OR(D31="",G31=""),"",D31-G31),"") | M31: =(B31/$C$19) | P31: =(E31/$F$19)
... A41: 수 출 제 비 용 | B41: =IFERROR(INDEX(손익계산서!$B:$B,MATCH($I41,손익계산서!$G:$G,0)),0) | C41: =IFERROR(INDEX(손익계산서!$C:$C,MATCH($I41,손익계산서!$G:$G,0)),0) | D41: =B41/$C$9 | E41: =IFERROR(INDEX(손익계산서!$D:$D,MATCH($I41,손익계산서!$G:$G,0)),0) | F41: =IFERROR(INDEX(손익계산서!$E:$E,MATCH($I41,손익계산서!$G:$G,0)),0) | G41: =E41/F$9 | H41: =SUBSTITUTE(A41," ","") | I41: =H41&"|"&COUNTIF($H$9:H41,H41) | J41: =IF($A41="","",IF(ISNUMBER(MATCH($I41,손익계산서!$G:$G,0)),"✓ 일치","⚠ 확인필요")) | K41: =IFERROR(IF(OR(D41="",G41=""),"",D41-G41),"") | M41: =(B41/$C$19) | P41: =(E41/$F$19)
A42: Ⅴ . 영 업 이 익 | B42: =IFERROR(INDEX(손익계산서!$B:$B,MATCH($I42,손익계산서!$G:$G,0)),0) | C42: =IFERROR(INDEX(손익계산서!$C:$C,MATCH($I42,손익계산서!$G:$G,0)),0) | D42: =C42/C9 | E42: =IFERROR(INDEX(손익계산서!$D:$D,MATCH($I42,손익계산서!$G:$G,0)),0) | F42: =IFERROR(INDEX(손익계산서!$E:$E,MATCH($I42,손익계산서!$G:$G,0)),0) | G42: =F42/F9 | H42: =SUBSTITUTE(A42," ","") | I42: =H42&"|"&COUNTIF($H$9:H42,H42) | J42: =IF($A42="","",IF(ISNUMBER(MATCH($I42,손익계산서!$G:$G,0)),"✓ 일치","⚠ 확인필요")) | K42: =IFERROR(IF(OR(D42="",G42=""),"",D42-G42),"")
A43: Ⅵ . 영 업 외 수 익 | B43: =IFERROR(INDEX(손익계산서!$B:$B,MATCH($I43,손익계산서!$G:$G,0)),0) | C43: =IFERROR(INDEX(손익계산서!$C:$C,MATCH($I43,손익계산서!$G:$G,0)),0) | D43: =C43/$C$9 | E43: =IFERROR(INDEX(손익계산서!$D:$D,MATCH($I43,손익계산서!$G:$G,0)),0) | F43: =IFERROR(INDEX(손익계산서!$E:$E,MATCH($I43,손익계산서!$G:$G,0)),0) | G43: =F43/$F$9 | H43: =SUBSTITUTE(A43," ","") | I43: =H43&"|"&COUNTIF($H$9:H43,H43) | J43: =IF($A43="","",IF(ISNUMBER(MATCH($I43,손익계산서!$G:$G,0)),"✓ 일치","⚠ 확인필요")) | K43: =IFERROR(IF(OR(D43="",G43=""),"",D43-G43),"")
A44: 이 자 수 익 | B44: =IFERROR(INDEX(손익계산서!$B:$B,MATCH($I44,손익계산서!$G:$G,0)),0) | C44: =IFERROR(INDEX(손익계산서!$C:$C,MATCH($I44,손익계산서!$G:$G,0)),0) | D44: =B44/$C$9 | E44: =IFERROR(INDEX(손익계산서!$D:$D,MATCH($I44,손익계산서!$G:$G,0)),0) | F44: =IFERROR(INDEX(손익계산서!$E:$E,MATCH($I44,손익계산서!$G:$G,0)),0) | G44: =E44/F$9 | H44: =SUBSTITUTE(A44," ","") | I44: =H44&"|"&COUNTIF($H$9:H44,H44) | J44: =IF($A44="","",IF(ISNUMBER(MATCH($I44,손익계산서!$G:$G,0)),"✓ 일치","⚠ 확인필요")) | K44: =IFERROR(IF(OR(D44="",G44=""),"",D44-G44),"")
A45: 외 환 차 익 | B45: =IFERROR(INDEX(손익계산서!$B:$B,MATCH($I45,손익계산서!$G:$G,0)),0) | C45: =IFERROR(INDEX(손익계산서!$C:$C,MATCH($I45,손익계산서!$G:$G,0)),0) | D45: =B45/$C$9 | E45: =IFERROR(INDEX(손익계산서!$D:$D,MATCH($I45,손익계산서!$G:$G,0)),0) | F45: =IFERROR(INDEX(손익계산서!$E:$E,MATCH($I45,손익계산서!$G:$G,0)),0) | G45: =E45/F$9 | H45: =SUBSTITUTE(A45," ","") | I45: =H45&"|"&COUNTIF($H$9:H45,H45) | J45: =IF($A45="","",IF(ISNUMBER(MATCH($I45,손익계산서!$G:$G,0)),"✓ 일치","⚠ 확인필요")) | K45: =IFERROR(IF(OR(D45="",G45=""),"",D45-G45),"")
A46: 외 화 환 산 이 익 | B46: =IFERROR(INDEX(손익계산서!$B:$B,MATCH($I46,손익계산서!$G:$G,0)),0) | C46: =IFERROR(INDEX(손익계산서!$C:$C,MATCH($I46,손익계산서!$G:$G,0)),0) | D46: =B46/$C$9 | E46: =IFERROR(INDEX(손익계산서!$D:$D,MATCH($I46,손익계산서!$G:$G,0)),0) | F46: =IFERROR(INDEX(손익계산서!$E:$E,MATCH($I46,손익계산서!$G:$G,0)),0) | G46: =E46/F$9 | H46: =SUBSTITUTE(A46," ","") | I46: =H46&"|"&COUNTIF($H$9:H46,H46) | J46: =IF($A46="","",IF(ISNUMBER(MATCH($I46,손익계산서!$G:$G,0)),"✓ 일치","⚠ 확인필요")) | K46: =IFERROR(IF(OR(D46="",G46=""),"",D46-G46),"")
A47: 유형자산 처분이익 | B47: =IFERROR(INDEX(손익계산서!$B:$B,MATCH($I47,손익계산서!$G:$G,0)),0) | C47: =IFERROR(INDEX(손익계산서!$C:$C,MATCH($I47,손익계산서!$G:$G,0)),0) | D47: =B47/$C$9 | E47: =IFERROR(INDEX(손익계산서!$D:$D,MATCH($I47,손익계산서!$G:$G,0)),0) | F47: =IFERROR(INDEX(손익계산서!$E:$E,MATCH($I47,손익계산서!$G:$G,0)),0) | G47: =E47/F$9 | H47: =SUBSTITUTE(A47," ","") | I47: =H47&"|"&COUNTIF($H$9:H47,H47) | J47: =IF($A47="","",IF(ISNUMBER(MATCH($I47,손익계산서!$G:$G,0)),"✓ 일치","⚠ 확인필요")) | K47: =IFERROR(IF(OR(D47="",G47=""),"",D47-G47),"")
A48: 투자자산 처분이익 | B48: =IFERROR(INDEX(손익계산서!$B:$B,MATCH($I48,손익계산서!$G:$G,0)),0) | C48: =IFERROR(INDEX(손익계산서!$C:$C,MATCH($I48,손익계산서!$G:$G,0)),0) | D48: =B48/$C$9 | E48: =IFERROR(INDEX(손익계산서!$D:$D,MATCH($I48,손익계산서!$G:$G,0)),0) | F48: =IFERROR(INDEX(손익계산서!$E:$E,MATCH($I48,손익계산서!$G:$G,0)),0) | G48: =E48/F$9 | H48: =SUBSTITUTE(A48," ","") | I48: =H48&"|"&COUNTIF($H$9:H48,H48) | J48: =IF($A48="","",IF(ISNUMBER(MATCH($I48,손익계산서!$G:$G,0)),"✓ 일치","⚠ 확인필요")) | K48: =IFERROR(IF(OR(D48="",G48=""),"",D48-G48),"")
A49: 금융상품 처분이익 | B49: =IFERROR(INDEX(손익계산서!$B:$B,MATCH($I49,손익계산서!$G:$G,0)),0) | C49: =IFERROR(INDEX(손익계산서!$C:$C,MATCH($I49,손익계산서!$G:$G,0)),0) | D49: =B49/$C$9 | E49: =IFERROR(INDEX(손익계산서!$D:$D,MATCH($I49,손익계산서!$G:$G,0)),0) | F49: =IFERROR(INDEX(손익계산서!$E:$E,MATCH($I49,손익계산서!$G:$G,0)),0) | G49: =E49/F$9 | H49: =SUBSTITUTE(A49," ","") | I49: =H49&"|"&COUNTIF($H$9:H49,H49) | J49: =IF($A49="","",IF(ISNUMBER(MATCH($I49,손익계산서!$G:$G,0)),"✓ 일치","⚠ 확인필요")) | K49: =IFERROR(IF(OR(D49="",G49=""),"",D49-G49),"")
A50: 잡 이 익 | B50: =IFERROR(INDEX(손익계산서!$B:$B,MATCH($I50,손익계산서!$G:$G,0)),0) | C50: =IFERROR(INDEX(손익계산서!$C:$C,MATCH($I50,손익계산서!$G:$G,0)),0) | D50: =B50/$C$9 | E50: =IFERROR(INDEX(손익계산서!$D:$D,MATCH($I50,손익계산서!$G:$G,0)),0) | F50: =IFERROR(INDEX(손익계산서!$E:$E,MATCH($I50,손익계산서!$G:$G,0)),0) | G50: =E50/F$9 | H50: =SUBSTITUTE(A50," ","") | I50: =H50&"|"&COUNTIF($H$9:H50,H50) | J50: =IF($A50="","",IF(ISNUMBER(MATCH($I50,손익계산서!$G:$G,0)),"✓ 일치","⚠ 확인필요")) | K50: =IFERROR(IF(OR(D50="",G50=""),"",D50-G50),"")
A51: Ⅶ . 영 업 외 비 용 | B51: =IFERROR(INDEX(손익계산서!$B:$B,MATCH($I51,손익계산서!$G:$G,0)),0) | C51: =IFERROR(INDEX(손익계산서!$C:$C,MATCH($I51,손익계산서!$G:$G,0)),0) | D51: =C51/$C$9 | E51: =IFERROR(INDEX(손익계산서!$D:$D,MATCH($I51,손익계산서!$G:$G,0)),0) | F51: =IFERROR(INDEX(손익계산서!$E:$E,MATCH($I51,손익계산서!$G:$G,0)),0) | G51: =F51/F$9 | H51: =SUBSTITUTE(A51," ","") | I51: =H51&"|"&COUNTIF($H$9:H51,H51) | J51: =IF($A51="","",IF(ISNUMBER(MATCH($I51,손익계산서!$G:$G,0)),"✓ 일치","⚠ 확인필요")) | K51: =IFERROR(IF(OR(D51="",G51=""),"",D51-G51),"")
...

Sheet 전월대비증감
A1: ="손익계산서(전월대비 증감내역)"
A3: ="기간 : "&TEXT(EOMONTH(인덱스!$K$1,-2)+1,"yyyy")&"년"&TEXT(MONTH(EOMONTH(인덱스!$K$1,-2)+1),"00")&"월"&TEXT(DAY(EOMONTH(인덱스!$K$1,-2)+1),"00")&"일"&"부터 - "&TEXT(인덱스!$K$1,"yyyy")&"년"&TEXT(MONTH(인덱스!$K$1),"00")&"월"&TEXT(DAY(인덱스!$K$1),"00")&"일"&"까지"
A5: ㈜창현 | M5: 단위 : 원
A6: 과 목 | B6: 계 | C6: 1월 | D6: 2월 | E6: 3월 | F6: 4월 | G6: 5월 | H6: 6월 | I6: ="전월("&MONTH(EOMONTH(인덱스!$K$1,-1))&"월)" | J6: ="당월("&MONTH(인덱스!$K$1)&"월)" | K6: 증감액 (전월대비) | L6: 증감 (전월대비) | M6: 내역 | P6: 일치확인 | Q6: 증감률
A7: Ⅰ . 매 출 액 | B7: =IFERROR(INDEX(기간별손익계산서!$B:$B,MATCH($O7,기간별손익계산서!$Q:$Q,0)),0) | C7: =IFERROR(INDEX(기간별손익계산서!$C:$N,MATCH($O7,기간별손익계산서!$Q:$Q,0),1),0) | D7: =IFERROR(INDEX(기간별손익계산서!$C:$N,MATCH($O7,기간별손익계산서!$Q:$Q,0),2),0) | E7: =IFERROR(INDEX(기간별손익계산서!$C:$N,MATCH($O7,기간별손익계산서!$Q:$Q,0),3),0) | F7: =IFERROR(INDEX(기간별손익계산서!$C:$N,MATCH($O7,기간별손익계산서!$Q:$Q,0),4),0) | G7: =IFERROR(INDEX(기간별손익계산서!$C:$N,MATCH($O7,기간별손익계산서!$Q:$Q,0),5),0) | H7: =IFERROR(INDEX(기간별손익계산서!$C:$N,MATCH($O7,기간별손익계산서!$Q:$Q,0),6),0) | I7: =IFERROR(INDEX(기간별손익계산서!$C:$N,MATCH($O7,기간별손익계산서!$Q:$Q,0),MONTH(EOMONTH(인덱스!$K$1,-1))),0) | J7: =IFERROR(INDEX(기간별손익계산서!$C:$N,MATCH($O7,기간별손익계산서!$Q:$Q,0),MONTH(인덱스!$K$1)),0) | K7: =J7-I7 | L7: =IF(J7-I7>0,"증가",IF(J7-I7=0,"변동없음","감소")) | N7: =SUBSTITUTE(A7," ","") | O7: =N7&"|"&COUNTIF($N$7:N7,N7) | P7: =IF($A7="","",IF(ISNUMBER(MATCH($O7,기간별손익계산서!$Q:$Q,0)),"✓ 일치","⚠ 확인필요")) | Q7: =IFERROR(IF(I7=0,"",(J7-I7)/ABS(I7)),"")
A8: 상 품 매 출 | B8: =IFERROR(INDEX(기간별손익계산서!$B:$B,MATCH($O8,기간별손익계산서!$Q:$Q,0)),0) | C8: =IFERROR(INDEX(기간별손익계산서!$C:$N,MATCH($O8,기간별손익계산서!$Q:$Q,0),1),0) | D8: =IFERROR(INDEX(기간별손익계산서!$C:$N,MATCH($O8,기간별손익계산서!$Q:$Q,0),2),0) | E8: =IFERROR(INDEX(기간별손익계산서!$C:$N,MATCH($O8,기간별손익계산서!$Q:$Q,0),3),0) | F8: =IFERROR(INDEX(기간별손익계산서!$C:$N,MATCH($O8,기간별손익계산서!$Q:$Q,0),4),0) | G8: =IFERROR(INDEX(기간별손익계산서!$C:$N,MATCH($O8,기간별손익계산서!$Q:$Q,0),5),0) | H8: =IFERROR(INDEX(기간별손익계산서!$C:$N,MATCH($O8,기간별손익계산서!$Q:$Q,0),6),0) | I8: =IFERROR(INDEX(기간별손익계산서!$C:$N,MATCH($O8,기간별손익계산서!$Q:$Q,0),MONTH(EOMONTH(인덱스!$K$1,-1))),0) | J8: =IFERROR(INDEX(기간별손익계산서!$C:$N,MATCH($O8,기간별손익계산서!$Q:$Q,0),MONTH(인덱스!$K$1)),0) | K8: =J8-I8 | N8: =SUBSTITUTE(A8," ","") | O8: =N8&"|"&COUNTIF($N$7:N8,N8) | P8: =IF($A8="","",IF(ISNUMBER(MATCH($O8,기간별손익계산서!$Q:$Q,0)),"✓ 일치","⚠ 확인필요")) | Q8: =IFERROR(IF(I8=0,"",(J8-I8)/ABS(I8)),"")
A9: 상 품 수 출 매 출 | B9: =IFERROR(INDEX(기간별손익계산서!$B:$B,MATCH($O9,기간별손익계산서!$Q:$Q,0)),0) | C9: =IFERROR(INDEX(기간별손익계산서!$C:$N,MATCH($O9,기간별손익계산서!$Q:$Q,0),1),0) | D9: =IFERROR(INDEX(기간별손익계산서!$C:$N,MATCH($O9,기간별손익계산서!$Q:$Q,0),2),0) | E9: =IFERROR(INDEX(기간별손익계산서!$C:$N,MATCH($O9,기간별손익계산서!$Q:$Q,0),3),0) | F9: =IFERROR(INDEX(기간별손익계산서!$C:$N,MATCH($O9,기간별손익계산서!$Q:$Q,0),4),0) | G9: =IFERROR(INDEX(기간별손익계산서!$C:$N,MATCH($O9,기간별손익계산서!$Q:$Q,0),5),0) | H9: =IFERROR(INDEX(기간별손익계산서!$C:$N,MATCH($O9,기간별손익계산서!$Q:$Q,0),6),0) | I9: =IFERROR(INDEX(기간별손익계산서!$C:$N,MATCH($O9,기간별손익계산서!$Q:$Q,0),MONTH(EOMONTH(인덱스!$K$1,-1))),0) | J9: =IFERROR(INDEX(기간별손익계산서!$C:$N,MATCH($O9,기간별손익계산서!$Q:$Q,0),MONTH(인덱스!$K$1)),0) | K9: =J9-I9 | N9: =SUBSTITUTE(A9," ","") | O9: =N9&"|"&COUNTIF($N$7:N9,N9) | P9: =IF($A9="","",IF(ISNUMBER(MATCH($O9,기간별손익계산서!$Q:$Q,0)),"✓ 일치","⚠ 확인필요")) | Q9: =IFERROR(IF(I9=0,"",(J9-I9)/ABS(I9)),"")
A10: Ⅱ . 매 출 원 가 | B10: =IFERROR(INDEX(기간별손익계산서!$B:$B,MATCH($O10,기간별손익계산서!$Q:$Q,0)),0) | C10: =IFERROR(INDEX(기간별손익계산서!$C:$N,MATCH($O10,기간별손익계산서!$Q:$Q,0),1),0) | D10: =IFERROR(INDEX(기간별손익계산서!$C:$N,MATCH($O10,기간별손익계산서!$Q:$Q,0),2),0) | E10: =IFERROR(INDEX(기간별손익계산서!$C:$N,MATCH($O10,기간별손익계산서!$Q:$Q,0),3),0) | F10: =IFERROR(INDEX(기간별손익계산서!$C:$N,MATCH($O10,기간별손익계산서!$Q:$Q,0),4),0) | G10: =IFERROR(INDEX(기간별손익계산서!$C:$N,MATCH($O10,기간별손익계산서!$Q:$Q,0),5),0) | H10: =IFERROR(INDEX(기간별손익계산서!$C:$N,MATCH($O10,기간별손익계산서!$Q:$Q,0),6),0) | I10: =IFERROR(INDEX(기간별손익계산서!$C:$N,MATCH($O10,기간별손익계산서!$Q:$Q,0),MONTH(EOMONTH(인덱스!$K$1,-1))),0) | J10: =IFERROR(INDEX(기간별손익계산서!$C:$N,MATCH($O10,기간별손익계산서!$Q:$Q,0),MONTH(인덱스!$K$1)),0) | K10: =J10-I10 | L10: =IF(J10-I10>0,"증가",IF(J10-I10=0,"변동없음","감소")) | N10: =SUBSTITUTE(A10," ","") | O10: =N10&"|"&COUNTIF($N$7:N10,N10) | P10: =IF($A10="","",IF(ISNUMBER(MATCH($O10,기간별손익계산서!$Q:$Q,0)),"✓ 일치","⚠ 확인필요")) | Q10: =IFERROR(IF(I10=0,"",(J10-I10)/ABS(I10)),"")
A11: 상 품 매 출 원 가 | B11: =IFERROR(INDEX(기간별손익계산서!$B:$B,MATCH($O11,기간별손익계산서!$Q:$Q,0)),0) | C11: =IFERROR(INDEX(기간별손익계산서!$C:$N,MATCH($O11,기간별손익계산서!$Q:$Q,0),1),0) | D11: =IFERROR(INDEX(기간별손익계산서!$C:$N,MATCH($O11,기간별손익계산서!$Q:$Q,0),2),0) | E11: =IFERROR(INDEX(기간별손익계산서!$C:$N,MATCH($O11,기간별손익계산서!$Q:$Q,0),3),0) | F11: =IFERROR(INDEX(기간별손익계산서!$C:$N,MATCH($O11,기간별손익계산서!$Q:$Q,0),4),0) | G11: =IFERROR(INDEX(기간별손익계산서!$C:$N,MATCH($O11,기간별손익계산서!$Q:$Q,0),5),0) | H11: =IFERROR(INDEX(기간별손익계산서!$C:$N,MATCH($O11,기간별손익계산서!$Q:$Q,0),6),0) | I11: =IFERROR(INDEX(기간별손익계산서!$C:$N,MATCH($O11,기간별손익계산서!$Q:$Q,0),MONTH(EOMONTH(인덱스!$K$1,-1))),0) | J11: =IFERROR(INDEX(기간별손익계산서!$C:$N,MATCH($O11,기간별손익계산서!$Q:$Q,0),MONTH(인덱스!$K$1)),0) | K11: =J11-I11 | N11: =SUBSTITUTE(A11," ","") | O11: =N11&"|"&COUNTIF($N$7:N11,N11) | P11: =IF($A11="","",IF(ISNUMBER(MATCH($O11,기간별손익계산서!$Q:$Q,0)),"✓ 일치","⚠ 확인필요")) | Q11: =IFERROR(IF(I11=0,"",(J11-I11)/ABS(I11)),"")
A12: 기초 상품 재고액 | B12: =IFERROR(INDEX(기간별손익계산서!$B:$B,MATCH($O12,기간별손익계산서!$Q:$Q,0)),0) | C12: =IFERROR(INDEX(기간별손익계산서!$C:$N,MATCH($O12,기간별손익계산서!$Q:$Q,0),1),0) | D12: =IFERROR(INDEX(기간별손익계산서!$C:$N,MATCH($O12,기간별손익계산서!$Q:$Q,0),2),0) | E12: =IFERROR(INDEX(기간별손익계산서!$C:$N,MATCH($O12,기간별손익계산서!$Q:$Q,0),3),0) | F12: =IFERROR(INDEX(기간별손익계산서!$C:$N,MATCH($O12,기간별손익계산서!$Q:$Q,0),4),0) | G12: =IFERROR(INDEX(기간별손익계산서!$C:$N,MATCH($O12,기간별손익계산서!$Q:$Q,0),5),0) | H12: =IFERROR(INDEX(기간별손익계산서!$C:$N,MATCH($O12,기간별손익계산서!$Q:$Q,0),6),0) | I12: =IFERROR(INDEX(기간별손익계산서!$C:$N,MATCH($O12,기간별손익계산서!$Q:$Q,0),MONTH(EOMONTH(인덱스!$K$1,-1))),0) | J12: =IFERROR(INDEX(기간별손익계산서!$C:$N,MATCH($O12,기간별손익계산서!$Q:$Q,0),MONTH(인덱스!$K$1)),0) | K12: =J12-I12 | N12: =SUBSTITUTE(A12," ","") | O12: =N12&"|"&COUNTIF($N$7:N12,N12) | P12: =IF($A12="","",IF(ISNUMBER(MATCH($O12,기간별손익계산서!$Q:$Q,0)),"✓ 일치","⚠ 확인필요")) | Q12: =IFERROR(IF(I12=0,"",(J12-I12)/ABS(I12)),"")
A13: 당기 상품 매 입 액 | B13: =IFERROR(INDEX(기간별손익계산서!$B:$B,MATCH($O13,기간별손익계산서!$Q:$Q,0)),0) | C13: =IFERROR(INDEX(기간별손익계산서!$C:$N,MATCH($O13,기간별손익계산서!$Q:$Q,0),1),0) | D13: =IFERROR(INDEX(기간별손익계산서!$C:$N,MATCH($O13,기간별손익계산서!$Q:$Q,0),2),0) | E13: =IFERROR(INDEX(기간별손익계산서!$C:$N,MATCH($O13,기간별손익계산서!$Q:$Q,0),3),0) | F13: =IFERROR(INDEX(기간별손익계산서!$C:$N,MATCH($O13,기간별손익계산서!$Q:$Q,0),4),0) | G13: =IFERROR(INDEX(기간별손익계산서!$C:$N,MATCH($O13,기간별손익계산서!$Q:$Q,0),5),0) | H13: =IFERROR(INDEX(기간별손익계산서!$C:$N,MATCH($O13,기간별손익계산서!$Q:$Q,0),6),0) | I13: =IFERROR(INDEX(기간별손익계산서!$C:$N,MATCH($O13,기간별손익계산서!$Q:$Q,0),MONTH(EOMONTH(인덱스!$K$1,-1))),0) | J13: =IFERROR(INDEX(기간별손익계산서!$C:$N,MATCH($O13,기간별손익계산서!$Q:$Q,0),MONTH(인덱스!$K$1)),0) | K13: =J13-I13 | N13: =SUBSTITUTE(A13," ","") | O13: =N13&"|"&COUNTIF($N$7:N13,N13) | P13: =IF($A13="","",IF(ISNUMBER(MATCH($O13,기간별손익계산서!$Q:$Q,0)),"✓ 일치","⚠ 확인필요")) | Q13: =IFERROR(IF(I13=0,"",(J13-I13)/ABS(I13)),"")
A14: 매 입 할 인 | B14: =IFERROR(INDEX(기간별손익계산서!$B:$B,MATCH($O14,기간별손익계산서!$Q:$Q,0)),0) | C14: =IFERROR(INDEX(기간별손익계산서!$C:$N,MATCH($O14,기간별손익계산서!$Q:$Q,0),1),0) | D14: =IFERROR(INDEX(기간별손익계산서!$C:$N,MATCH($O14,기간별손익계산서!$Q:$Q,0),2),0) | E14: =IFERROR(INDEX(기간별손익계산서!$C:$N,MATCH($O14,기간별손익계산서!$Q:$Q,0),3),0) | F14: =IFERROR(INDEX(기간별손익계산서!$C:$N,MATCH($O14,기간별손익계산서!$Q:$Q,0),4),0) | G14: =IFERROR(INDEX(기간별손익계산서!$C:$N,MATCH($O14,기간별손익계산서!$Q:$Q,0),5),0) | H14: =IFERROR(INDEX(기간별손익계산서!$C:$N,MATCH($O14,기간별손익계산서!$Q:$Q,0),6),0) | I14: =IFERROR(INDEX(기간별손익계산서!$C:$N,MATCH($O14,기간별손익계산서!$Q:$Q,0),MONTH(EOMONTH(인덱스!$K$1,-1))),0) | J14: =IFERROR(INDEX(기간별손익계산서!$C:$N,MATCH($O14,기간별손익계산서!$Q:$Q,0),MONTH(인덱스!$K$1)),0) | K14: =J14-I14 | N14: =SUBSTITUTE(A14," ","") | O14: =N14&"|"&COUNTIF($N$7:N14,N14) | P14: =IF($A14="","",IF(ISNUMBER(MATCH($O14,기간별손익계산서!$Q:$Q,0)),"✓ 일치","⚠ 확인필요")) | Q14: =IFERROR(IF(I14=0,"",(J14-I14)/ABS(I14)),"")
A15: 기말 상품 재고액 | B15: =IFERROR(INDEX(기간별손익계산서!$B:$B,MATCH($O15,기간별손익계산서!$Q:$Q,0)),0) | C15: =IFERROR(INDEX(기간별손익계산서!$C:$N,MATCH($O15,기간별손익계산서!$Q:$Q,0),1),0) | D15: =IFERROR(INDEX(기간별손익계산서!$C:$N,MATCH($O15,기간별손익계산서!$Q:$Q,0),2),0) | E15: =IFERROR(INDEX(기간별손익계산서!$C:$N,MATCH($O15,기간별손익계산서!$Q:$Q,0),3),0) | F15: =IFERROR(INDEX(기간별손익계산서!$C:$N,MATCH($O15,기간별손익계산서!$Q:$Q,0),4),0) | G15: =IFERROR(INDEX(기간별손익계산서!$C:$N,MATCH($O15,기간별손익계산서!$Q:$Q,0),5),0) | H15: =IFERROR(INDEX(기간별손익계산서!$C:$N,MATCH($O15,기간별손익계산서!$Q:$Q,0),6),0) | I15: =IFERROR(INDEX(기간별손익계산서!$C:$N,MATCH($O15,기간별손익계산서!$Q:$Q,0),MONTH(EOMONTH(인덱스!$K$1,-1))),0) | J15: =IFERROR(INDEX(기간별손익계산서!$C:$N,MATCH($O15,기간별손익계산서!$Q:$Q,0),MONTH(인덱스!$K$1)),0) | K15: =J15-I15 | N15: =SUBSTITUTE(A15," ","") | O15: =N15&"|"&COUNTIF($N$7:N15,N15) | P15: =IF($A15="","",IF(ISNUMBER(MATCH($O15,기간별손익계산서!$Q:$Q,0)),"✓ 일치","⚠ 확인필요")) | Q15: =IFERROR(IF(I15=0,"",(J15-I15)/ABS(I15)),"")
A16: Ⅲ . 매 출 총 이 익 | B16: =IFERROR(INDEX(기간별손익계산서!$B:$B,MATCH($O16,기간별손익계산서!$Q:$Q,0)),0) | C16: =IFERROR(INDEX(기간별손익계산서!$C:$N,MATCH($O16,기간별손익계산서!$Q:$Q,0),1),0) | D16: =IFERROR(INDEX(기간별손익계산서!$C:$N,MATCH($O16,기간별손익계산서!$Q:$Q,0),2),0) | E16: =IFERROR(INDEX(기간별손익계산서!$C:$N,MATCH($O16,기간별손익계산서!$Q:$Q,0),3),0) | F16: =IFERROR(INDEX(기간별손익계산서!$C:$N,MATCH($O16,기간별손익계산서!$Q:$Q,0),4),0) | G16: =IFERROR(INDEX(기간별손익계산서!$C:$N,MATCH($O16,기간별손익계산서!$Q:$Q,0),5),0) | H16: =IFERROR(INDEX(기간별손익계산서!$C:$N,MATCH($O16,기간별손익계산서!$Q:$Q,0),6),0) | I16: =IFERROR(INDEX(기간별손익계산서!$C:$N,MATCH($O16,기간별손익계산서!$Q:$Q,0),MONTH(EOMONTH(인덱스!$K$1,-1))),0) | J16: =IFERROR(INDEX(기간별손익계산서!$C:$N,MATCH($O16,기간별손익계산서!$Q:$Q,0),MONTH(인덱스!$K$1)),0) | K16: =J16-I16 | L16: =IF(J16-I16>0,"증가",IF(J16-I16=0,"변동없음","감소")) | N16: =SUBSTITUTE(A16," ","") | O16: =N16&"|"&COUNTIF($N$7:N16,N16) | P16: =IF($A16="","",IF(ISNUMBER(MATCH($O16,기간별손익계산서!$Q:$Q,0)),"✓ 일치","⚠ 확인필요")) | Q16: =IFERROR(IF(I16=0,"",(J16-I16)/ABS(I16)),"")
A17: Ⅳ . 판 매 관 리 비 | B17: =IFERROR(INDEX(기간별손익계산서!$B:$B,MATCH($O17,기간별손익계산서!$Q:$Q,0)),0) | C17: =IFERROR(INDEX(기간별손익계산서!$C:$N,MATCH($O17,기간별손익계산서!$Q:$Q,0),1),0) | D17: =IFERROR(INDEX(기간별손익계산서!$C:$N,MATCH($O17,기간별손익계산서!$Q:$Q,0),2),0) | E17: =IFERROR(INDEX(기간별손익계산서!$C:$N,MATCH($O17,기간별손익계산서!$Q:$Q,0),3),0) | F17: =IFERROR(INDEX(기간별손익계산서!$C:$N,MATCH($O17,기간별손익계산서!$Q:$Q,0),4),0) | G17: =IFERROR(INDEX(기간별손익계산서!$C:$N,MATCH($O17,기간별손익계산서!$Q:$Q,0),5),0) | H17: =IFERROR(INDEX(기간별손익계산서!$C:$N,MATCH($O17,기간별손익계산서!$Q:$Q,0),6),0) | I17: =IFERROR(INDEX(기간별손익계산서!$C:$N,MATCH($O17,기간별손익계산서!$Q:$Q,0),MONTH(EOMONTH(인덱스!$K$1,-1))),0) | J17: =IFERROR(INDEX(기간별손익계산서!$C:$N,MATCH($O17,기간별손익계산서!$Q:$Q,0),MONTH(인덱스!$K$1)),0) | K17: =J17-I17 | L17: =IF(J17-I17>0,"증가",IF(J17-I17=0,"변동없음","감소")) | N17: =SUBSTITUTE(A17," ","") | O17: =N17&"|"&COUNTIF($N$7:N17,N17) | P17: =IF($A17="","",IF(ISNUMBER(MATCH($O17,기간별손익계산서!$Q:$Q,0)),"✓ 일치","⚠ 확인필요")) | Q17: =IFERROR(IF(I17=0,"",(J17-I17)/ABS(I17)),"")
A18: 직 원 급 여 | B18: =IFERROR(INDEX(기간별손익계산서!$B:$B,MATCH($O18,기간별손익계산서!$Q:$Q,0)),0) | C18: =IFERROR(INDEX(기간별손익계산서!$C:$N,MATCH($O18,기간별손익계산서!$Q:$Q,0),1),0) | D18: =IFERROR(INDEX(기간별손익계산서!$C:$N,MATCH($O18,기간별손익계산서!$Q:$Q,0),2),0) | E18: =IFERROR(INDEX(기간별손익계산서!$C:$N,MATCH($O18,기간별손익계산서!$Q:$Q,0),3),0) | F18: =IFERROR(INDEX(기간별손익계산서!$C:$N,MATCH($O18,기간별손익계산서!$Q:$Q,0),4),0) | G18: =IFERROR(INDEX(기간별손익계산서!$C:$N,MATCH($O18,기간별손익계산서!$Q:$Q,0),5),0) | H18: =IFERROR(INDEX(기간별손익계산서!$C:$N,MATCH($O18,기간별손익계산서!$Q:$Q,0),6),0) | I18: =IFERROR(INDEX(기간별손익계산서!$C:$N,MATCH($O18,기간별손익계산서!$Q:$Q,0),MONTH(EOMONTH(인덱스!$K$1,-1))),0) | J18: =IFERROR(INDEX(기간별손익계산서!$C:$N,MATCH($O18,기간별손익계산서!$Q:$Q,0),MONTH(인덱스!$K$1)),0) | K18: =J18-I18 | L18: =IF(J18-I18>0,"증가",IF(J18-I18=0,"변동없음","감소")) | M18: 6월: 총36명, 7월: 총36명 | N18: =SUBSTITUTE(A18," ","") | O18: =N18&"|"&COUNTIF($N$7:N18,N18) | P18: =IF($A18="","",IF(ISNUMBER(MATCH($O18,기간별손익계산서!$Q:$Q,0)),"✓ 일치","⚠ 확인필요")) | Q18: =IFERROR(IF(I18=0,"",(J18-I18)/ABS(I18)),"")
A19: 잡 급 | B19: =IFERROR(INDEX(기간별손익계산서!$B:$B,MATCH($O19,기간별손익계산서!$Q:$Q,0)),0) | C19: =IFERROR(INDEX(기간별손익계산서!$C:$N,MATCH($O19,기간별손익계산서!$Q:$Q,0),1),0) | D19: =IFERROR(INDEX(기간별손익계산서!$C:$N,MATCH($O19,기간별손익계산서!$Q:$Q,0),2),0) | E19: =IFERROR(INDEX(기간별손익계산서!$C:$N,MATCH($O19,기간별손익계산서!$Q:$Q,0),3),0) | F19: =IFERROR(INDEX(기간별손익계산서!$C:$N,MATCH($O19,기간별손익계산서!$Q:$Q,0),4),0) | G19: =IFERROR(INDEX(기간별손익계산서!$C:$N,MATCH($O19,기간별손익계산서!$Q:$Q,0),5),0) | H19: =IFERROR(INDEX(기간별손익계산서!$C:$N,MATCH($O19,기간별손익계산서!$Q:$Q,0),6),0) | I19: =IFERROR(INDEX(기간별손익계산서!$C:$N,MATCH($O19,기간별손익계산서!$Q:$Q,0),MONTH(EOMONTH(인덱스!$K$1,-1))),0) | J19: =IFERROR(INDEX(기간별손익계산서!$C:$N,MATCH($O19,기간별손익계산서!$Q:$Q,0),MONTH(인덱스!$K$1)),0) | K19: =J19-I19 | L19: =IF(J19-I19>0,"증가",IF(J19-I19=0,"변동없음","감소")) | N19: =SUBSTITUTE(A19," ","") | O19: =N19&"|"&COUNTIF($N$7:N19,N19) | P19: =IF($A19="","",IF(ISNUMBER(MATCH($O19,기간별손익계산서!$Q:$Q,0)),"✓ 일치","⚠ 확인필요")) | Q19: =IFERROR(IF(I19=0,"",(J19-I19)/ABS(I19)),"")
A20: 상 여 금 | B20: =IFERROR(INDEX(기간별손익계산서!$B:$B,MATCH($O20,기간별손익계산서!$Q:$Q,0)),0) | C20: =IFERROR(INDEX(기간별손익계산서!$C:$N,MATCH($O20,기간별손익계산서!$Q:$Q,0),1),0) | D20: =IFERROR(INDEX(기간별손익계산서!$C:$N,MATCH($O20,기간별손익계산서!$Q:$Q,0),2),0) | E20: =IFERROR(INDEX(기간별손익계산서!$C:$N,MATCH($O20,기간별손익계산서!$Q:$Q,0),3),0) | F20: =IFERROR(INDEX(기간별손익계산서!$C:$N,MATCH($O20,기간별손익계산서!$Q:$Q,0),4),0) | G20: =IFERROR(INDEX(기간별손익계산서!$C:$N,MATCH($O20,기간별손익계산서!$Q:$Q,0),5),0) | H20: =IFERROR(INDEX(기간별손익계산서!$C:$N,MATCH($O20,기간별손익계산서!$Q:$Q,0),6),0) | I20: =IFERROR(INDEX(기간별손익계산서!$C:$N,MATCH($O20,기간별손익계산서!$Q:$Q,0),MONTH(EOMONTH(인덱스!$K$1,-1))),0) | J20: =IFERROR(INDEX(기간별손익계산서!$C:$N,MATCH($O20,기간별손익계산서!$Q:$Q,0),MONTH(인덱스!$K$1)),0) | K20: =J20-I20 | L20: =IF(J20-I20>0,"증가",IF(J20-I20=0,"변동없음","감소")) | N20: =SUBSTITUTE(A20," ","") | O20: =N20&"|"&COUNTIF($N$7:N20,N20) | P20: =IF($A20="","",IF(ISNUMBER(MATCH($O20,기간별손익계산서!$Q:$Q,0)),"✓ 일치","⚠ 확인필요")) | Q20: =IFERROR(IF(I20=0,"",(J20-I20)/ABS(I20)),"")
A21: 퇴 직 급 여 | B21: =IFERROR(INDEX(기간별손익계산서!$B:$B,MATCH($O21,기간별손익계산서!$Q:$Q,0)),0) | C21: =IFERROR(INDEX(기간별손익계산서!$C:$N,MATCH($O21,기간별손익계산서!$Q:$Q,0),1),0) | D21: =IFERROR(INDEX(기간별손익계산서!$C:$N,MATCH($O21,기간별손익계산서!$Q:$Q,0),2),0) | E21: =IFERROR(INDEX(기간별손익계산서!$C:$N,MATCH($O21,기간별손익계산서!$Q:$Q,0),3),0) | F21: =IFERROR(INDEX(기간별손익계산서!$C:$N,MATCH($O21,기간별손익계산서!$Q:$Q,0),4),0) | G21: =IFERROR(INDEX(기간별손익계산서!$C:$N,MATCH($O21,기간별손익계산서!$Q:$Q,0),5),0) | H21: =IFERROR(INDEX(기간별손익계산서!$C:$N,MATCH($O21,기간별손익계산서!$Q:$Q,0),6),0) | I21: =IFERROR(INDEX(기간별손익계산서!$C:$N,MATCH($O21,기간별손익계산서!$Q:$Q,0),MONTH(EOMONTH(인덱스!$K$1,-1))),0) | J21: =IFERROR(INDEX(기간별손익계산서!$C:$N,MATCH($O21,기간별손익계산서!$Q:$Q,0),MONTH(인덱스!$K$1)),0) | K21: =J21-I21 | L21: =IF(J21-I21>0,"증가",IF(J21-I21=0,"변동없음","감소")) | M21: 6월:상반기 퇴직연금 불입 | N21: =SUBSTITUTE(A21," ","") | O21: =N21&"|"&COUNTIF($N$7:N21,N21) | P21: =IF($A21="","",IF(ISNUMBER(MATCH($O21,기간별손익계산서!$Q:$Q,0)),"✓ 일치","⚠ 확인필요")) | Q21: =IFERROR(IF(I21=0,"",(J21-I21)/ABS(I21)),"")
A22: 복 리 후 생 비 | B22: =IFERROR(INDEX(기간별손익계산서!$B:$B,MATCH($O22,기간별손익계산서!$Q:$Q,0)),0) | C22: =IFERROR(INDEX(기간별손익계산서!$C:$N,MATCH($O22,기간별손익계산서!$Q:$Q,0),1),0) | D22: =IFERROR(INDEX(기간별손익계산서!$C:$N,MATCH($O22,기간별손익계산서!$Q:$Q,0),2),0) | E22: =IFERROR(INDEX(기간별손익계산서!$C:$N,MATCH($O22,기간별손익계산서!$Q:$Q,0),3),0) | F22: =IFERROR(INDEX(기간별손익계산서!$C:$N,MATCH($O22,기간별손익계산서!$Q:$Q,0),4),0) | G22: =IFERROR(INDEX(기간별손익계산서!$C:$N,MATCH($O22,기간별손익계산서!$Q:$Q,0),5),0) | H22: =IFERROR(INDEX(기간별손익계산서!$C:$N,MATCH($O22,기간별손익계산서!$Q:$Q,0),6),0) | I22: =IFERROR(INDEX(기간별손익계산서!$C:$N,MATCH($O22,기간별손익계산서!$Q:$Q,0),MONTH(EOMONTH(인덱스!$K$1,-1))),0) | J22: =IFERROR(INDEX(기간별손익계산서!$C:$N,MATCH($O22,기간별손익계산서!$Q:$Q,0),MONTH(인덱스!$K$1)),0) | K22: =J22-I22 | L22: =IF(J22-I22>0,"증가",IF(J22-I22=0,"변동없음","감소")) | M22: 건강(요양)보험 회사부담금 | N22: =SUBSTITUTE(A22," ","") | O22: =N22&"|"&COUNTIF($N$7:N22,N22) | P22: =IF($A22="","",IF(ISNUMBER(MATCH($O22,기간별손익계산서!$Q:$Q,0)),"✓ 일치","⚠ 확인필요")) | Q22: =IFERROR(IF(I22=0,"",(J22-I22)/ABS(I22)),"")
A23: 여 비 교 통 비 | B23: =IFERROR(INDEX(기간별손익계산서!$B:$B,MATCH($O23,기간별손익계산서!$Q:$Q,0)),0) | C23: =IFERROR(INDEX(기간별손익계산서!$C:$N,MATCH($O23,기간별손익계산서!$Q:$Q,0),1),0) | D23: =IFERROR(INDEX(기간별손익계산서!$C:$N,MATCH($O23,기간별손익계산서!$Q:$Q,0),2),0) | E23: =IFERROR(INDEX(기간별손익계산서!$C:$N,MATCH($O23,기간별손익계산서!$Q:$Q,0),3),0) | F23: =IFERROR(INDEX(기간별손익계산서!$C:$N,MATCH($O23,기간별손익계산서!$Q:$Q,0),4),0) | G23: =IFERROR(INDEX(기간별손익계산서!$C:$N,MATCH($O23,기간별손익계산서!$Q:$Q,0),5),0) | H23: =IFERROR(INDEX(기간별손익계산서!$C:$N,MATCH($O23,기간별손익계산서!$Q:$Q,0),6),0) | I23: =IFERROR(INDEX(기간별손익계산서!$C:$N,MATCH($O23,기간별손익계산서!$Q:$Q,0),MONTH(EOMONTH(인덱스!$K$1,-1))),0) | J23: =IFERROR(INDEX(기간별손익계산서!$C:$N,MATCH($O23,기간별손익계산서!$Q:$Q,0),MONTH(인덱스!$K$1)),0) | K23: =J23-I23 | L23: =IF(J23-I23>0,"증가",IF(J23-I23=0,"변동없음","감소")) | M23: 출장경비 | N23: =SUBSTITUTE(A23," ","") | O23: =N23&"|"&COUNTIF($N$7:N23,N23) | P23: =IF($A23="","",IF(ISNUMBER(MATCH($O23,기간별손익계산서!$Q:$Q,0)),"✓ 일치","⚠ 확인필요")) | Q23: =IFERROR(IF(I23=0,"",(J23-I23)/ABS(I23)),"")
